Workbook

Sheet Year
Z1: =YEAR(TODAY()) -> 2026 | AA1: Create more with themes Go to Format >> Theme
B2: JANUARY | J2: FEBRUARY | R2: MARCH
B3: S | C3: M | D3: T | E3: W | F3: T | G3: F | H3: S | J3: S | K3: M | L3: T | M3: W | N3: T | O3: F | P3: S | R3: S | S3: M | T3: T | U3: W | V3: T | W3: F | X3: S
B4: =IF(WEEKDAY(DATEVALUE($Z$1&$B$2&1))=1,1,"") | C4: =IF(B4<>"",B4+1,IF(WEEKDAY(DATEVALUE($Z$1&$B$2&1))=2,1,"")) | D4: =IF(C4<>"",C4+1,IF(WEEKDAY(DATEVALUE($Z$1&$B$2&1))=3,1,"")) | E4: =IF(D4<>"",D4+1,IF(WEEKDAY(DATEVALUE($Z$1&$B$2&1))=4,1,"")) | F4: =IF(E4<>"",E4+1,IF(WEEKDAY(DATEVALUE($Z$1&$B$2&1))=5,1,"")) -> 1 | G4: =IF(F4<>"",F4+1,IF(WEEKDAY(DATEVALUE($Z$1&$B$2&1))=6,1,"")) -> 2 | H4: =IF(G4<>"",G4+1,IF(WEEKDAY(DATEVALUE($Z$1&$B$2&1))=7,1,"")) -> 3 | J4: =IF(WEEKDAY(DATEVALUE($Z$1&$J$2&1))=1,1,"") -> 1 | K4: =IF(J4<>"",J4+1,IF(WEEKDAY(DATEVALUE($Z$1&$J$2&1))=2,1,"")) -> 2 | L4: =IF(K4<>"",K4+1,IF(WEEKDAY(DATEVALUE($Z$1&$J$2&1))=3,1,"")) -> 3 | M4: =IF(L4<>"",L4+1,IF(WEEKDAY(DATEVALUE($Z$1&$J$2&1))=4,1,"")) -> 4 | N4: =IF(M4<>"",M4+1,IF(WEEKDAY(DATEVALUE($Z$1&$J$2&1))=5,1,"")) -> 5 | O4: =IF(N4<>"",N4+1,IF(WEEKDAY(DATEVALUE($Z$1&$J$2&1))=6,1,"")) -> 6 | P4: =IF(O4<>"",O4+1,IF(WEEKDAY(DATEVALUE($Z$1&$J$2&1))=7,1,"")) -> 7 | R4: =IF(WEEKDAY(DATEVALUE($Z$1&$R$2&1))=1,1,"") -> 1 | S4: =IF(R4<>"",R4+1,IF(WEEKDAY(DATEVALUE($Z$1&$R$2&1))=2,1,"")) -> 2 | T4: =IF(S4<>"",S4+1,IF(WEEKDAY(DATEVALUE($Z$1&$R$2&1))=3,1,"")) -> 3 | U4: =IF(T4<>"",T4+1,IF(WEEKDAY(DATEVALUE($Z$1&$R$2&1))=4,1,"")) -> 4 | V4: =IF(U4<>"",U4+1,IF(WEEKDAY(DATEVALUE($Z$1&$R$2&1))=5,1,"")) -> 5 | W4: =IF(V4<>"",V4+1,IF(WEEKDAY(DATEVALUE($Z$1&$R$2&1))=6,1,"")) -> 6 | X4: =IF(W4<>"",W4+1,IF(WEEKDAY(DATEVALUE($Z$1&$R$2&1))=7,1,"")) -> 7
B5: =IF(OR(H4="",VALUE(H4)>EOMONTH(DATEVALUE($Z$1&$B$2&1),0)-EOMONTH(DATEVALUE($Z$1&$B$2&1),-1)-1),"",H4+1) -> 4 | C5: =IF(OR(B5="",VALUE(B5)>EOMONTH(DATEVALUE($Z$1&$B$2&1),0)-EOMONTH(DATEVALUE($Z$1&$B$2&1),-1)-1),"",B5+1) -> 5 | D5: =IF(OR(C5="",VALUE(C5)>EOMONTH(DATEVALUE($Z$1&$B$2&1),0)-EOMONTH(DATEVALUE($Z$1&$B$2&1),-1)-1),"",C5+1) -> 6 | E5: =IF(OR(D5="",VALUE(D5)>EOMONTH(DATEVALUE($Z$1&$B$2&1),0)-EOMONTH(DATEVALUE($Z$1&$B$2&1),-1)-1),"",D5+1) -> 7 | F5: =IF(OR(E5="",VALUE(E5)>EOMONTH(DATEVALUE($Z$1&$B$2&1),0)-EOMONTH(DATEVALUE($Z$1&$B$2&1),-1)-1),"",E5+1) -> 8 | G5: =IF(OR(F5="",VALUE(F5)>EOMONTH(DATEVALUE($Z$1&$B$2&1),0)-EOMONTH(DATEVALUE($Z$1&$B$2&1),-1)-1),"",F5+1) -> 9 | H5: =IF(OR(G5="",VALUE(G5)>EOMONTH(DATEVALUE($Z$1&$B$2&1),0)-EOMONTH(DATEVALUE($Z$1&$B$2&1),-1)-1),"",G5+1) -> 10 | J5: =IF(OR(P4="",VALUE(P4)>EOMONTH(DATEVALUE($Z$1&$J$2&1),0)-EOMONTH(DATEVALUE($Z$1&$J$2&1),-1)-1),"",P4+1) -> 8 | K5: =IF(OR(J5="",VALUE(J5)>EOMONTH(DATEVALUE($Z$1&$J$2&1),0)-EOMONTH(DATEVALUE($Z$1&$J$2&1),-1)-1),"",J5+1) -> 9 | L5: =IF(OR(K5="",VALUE(K5)>EOMONTH(DATEVALUE($Z$1&$J$2&1),0)-EOMONTH(DATEVALUE($Z$1&$J$2&1),-1)-1),"",K5+1) -> 10 | M5: =IF(OR(L5="",VALUE(L5)>EOMONTH(DATEVALUE($Z$1&$J$2&1),0)-EOMONTH(DATEVALUE($Z$1&$J$2&1),-1)-1),"",L5+1) -> 11 | N5: =IF(OR(M5="",VALUE(M5)>EOMONTH(DATEVALUE($Z$1&$J$2&1),0)-EOMONTH(DATEVALUE($Z$1&$J$2&1),-1)-1),"",M5+1) -> 12 | O5: =IF(OR(N5="",VALUE(N5)>EOMONTH(DATEVALUE($Z$1&$J$2&1),0)-EOMONTH(DATEVALUE($Z$1&$J$2&1),-1)-1),"",N5+1) -> 13 | P5: =IF(OR(O5="",VALUE(O5)>EOMONTH(DATEVALUE($Z$1&$J$2&1),0)-EOMONTH(DATEVALUE($Z$1&$J$2&1),-1)-1),"",O5+1) -> 14 | R5: =IF(OR(X4="",VALUE(X4)>EOMONTH(DATEVALUE($Z$1&$R$2&1),0)-EOMONTH(DATEVALUE($Z$1&$R$2&1),-1)-1),"",X4+1) -> 8 | S5: =IF(OR(R5="",VALUE(R5)>EOMONTH(DATEVALUE($Z$1&$R$2&1),0)-EOMONTH(DATEVALUE($Z$1&$R$2&1),-1)-1),"",R5+1) -> 9 | T5: =IF(OR(S5="",VALUE(S5)>EOMONTH(DATEVALUE($Z$1&$R$2&1),0)-EOMONTH(DATEVALUE($Z$1&$R$2&1),-1)-1),"",S5+1) -> 10 | U5: =IF(OR(T5="",VALUE(T5)>EOMONTH(DATEVALUE($Z$1&$R$2&1),0)-EOMONTH(DATEVALUE($Z$1&$R$2&1),-1)-1),"",T5+1) -> 11 | V5: =IF(OR(U5="",VALUE(U5)>EOMONTH(DATEVALUE($Z$1&$R$2&1),0)-EOMONTH(DATEVALUE($Z$1&$R$2&1),-1)-1),"",U5+1) -> 12 | W5: =IF(OR(V5="",VALUE(V5)>EOMONTH(DATEVALUE($Z$1&$R$2&1),0)-EOMONTH(DATEVALUE($Z$1&$R$2&1),-1)-1),"",V5+1) -> 13 | X5: =IF(OR(W5="",VALUE(W5)>EOMONTH(DATEVALUE($Z$1&$R$2&1),0)-EOMONTH(DATEVALUE($Z$1&$R$2&1),-1)-1),"",W5+1) -> 14
B6: =IF(OR(H5="",VALUE(H5)>EOMONTH(DATEVALUE($Z$1&$B$2&1),0)-EOMONTH(DATEVALUE($Z$1&$B$2&1),-1)-1),"",H5+1) -> 11 | C6: =IF(OR(B6="",VALUE(B6)>EOMONTH(DATEVALUE($Z$1&$B$2&1),0)-EOMONTH(DATEVALUE($Z$1&$B$2&1),-1)-1),"",B6+1) -> 12 | D6: =IF(OR(C6="",VALUE(C6)>EOMONTH(DATEVALUE($Z$1&$B$2&1),0)-EOMONTH(DATEVALUE($Z$1&$B$2&1),-1)-1),"",C6+1) -> 13 | E6: =IF(OR(D6="",VALUE(D6)>EOMONTH(DATEVALUE($Z$1&$B$2&1),0)-EOMONTH(DATEVALUE($Z$1&$B$2&1),-1)-1),"",D6+1) -> 14 | F6: =IF(OR(E6="",VALUE(E6)>EOMONTH(DATEVALUE($Z$1&$B$2&1),0)-EOMONTH(DATEVALUE($Z$1&$B$2&1),-1)-1),"",E6+1) -> 15 | G6: =IF(OR(F6="",VALUE(F6)>EOMONTH(DATEVALUE($Z$1&$B$2&1),0)-EOMONTH(DATEVALUE($Z$1&$B$2&1),-1)-1),"",F6+1) -> 16 | H6: =IF(OR(G6="",VALUE(G6)>EOMONTH(DATEVALUE($Z$1&$B$2&1),0)-EOMONTH(DATEVALUE($Z$1&$B$2&1),-1)-1),"",G6+1) -> 17 | J6: =IF(OR(P5="",VALUE(P5)>EOMONTH(DATEVALUE($Z$1&$J$2&1),0)-EOMONTH(DATEVALUE($Z$1&$J$2&1),-1)-1),"",P5+1) -> 15 | K6: =IF(OR(J6="",VALUE(J6)>EOMONTH(DATEVALUE($Z$1&$J$2&1),0)-EOMONTH(DATEVALUE($Z$1&$J$2&1),-1)-1),"",J6+1) -> 16 | L6: =IF(OR(K6="",VALUE(K6)>EOMONTH(DATEVALUE($Z$1&$J$2&1),0)-EOMONTH(DATEVALUE($Z$1&$J$2&1),-1)-1),"",K6+1) -> 17 | M6: =IF(OR(L6="",VALUE(L6)>EOMONTH(DATEVALUE($Z$1&$J$2&1),0)-EOMONTH(DATEVALUE($Z$1&$J$2&1),-1)-1),"",L6+1) -> 18 | N6: =IF(OR(M6="",VALUE(M6)>EOMONTH(DATEVALUE($Z$1&$J$2&1),0)-EOMONTH(DATEVALUE($Z$1&$J$2&1),-1)-1),"",M6+1) -> 19 | O6: =IF(OR(N6="",VALUE(N6)>EOMONTH(DATEVALUE($Z$1&$J$2&1),0)-EOMONTH(DATEVALUE($Z$1&$J$2&1),-1)-1),"",N6+1) -> 20 | P6: =IF(OR(O6="",VALUE(O6)>EOMONTH(DATEVALUE($Z$1&$J$2&1),0)-EOMONTH(DATEVALUE($Z$1&$J$2&1),-1)-1),"",O6+1) -> 21 | R6: =IF(OR(X5="",VALUE(X5)>EOMONTH(DATEVALUE($Z$1&$R$2&1),0)-EOMONTH(DATEVALUE($Z$1&$R$2&1),-1)-1),"",X5+1) -> 15 | S6: =IF(OR(R6="",VALUE(R6)>EOMONTH(DATEVALUE($Z$1&$R$2&1),0)-EOMONTH(DATEVALUE($Z$1&$R$2&1),-1)-1),"",R6+1) -> 16 | T6: =IF(OR(S6="",VALUE(S6)>EOMONTH(DATEVALUE($Z$1&$R$2&1),0)-EOMONTH(DATEVALUE($Z$1&$R$2&1),-1)-1),"",S6+1) -> 17 | U6: =IF(OR(T6="",VALUE(T6)>EOMONTH(DATEVALUE($Z$1&$R$2&1),0)-EOMONTH(DATEVALUE($Z$1&$R$2&1),-1)-1),"",T6+1) -> 18 | V6: =IF(OR(U6="",VALUE(U6)>EOMONTH(DATEVALUE($Z$1&$R$2&1),0)-EOMONTH(DATEVALUE($Z$1&$R$2&1),-1)-1),"",U6+1) -> 19 | W6: =IF(OR(V6="",VALUE(V6)>EOMONTH(DATEVALUE($Z$1&$R$2&1),0)-EOMONTH(DATEVALUE($Z$1&$R$2&1),-1)-1),"",V6+1) -> 20 | X6: =IF(OR(W6="",VALUE(W6)>EOMONTH(DATEVALUE($Z$1&$R$2&1),0)-EOMONTH(DATEVALUE($Z$1&$R$2&1),-1)-1),"",W6+1) -> 21
B7: =IF(OR(H6="",VALUE(H6)>EOMONTH(DATEVALUE($Z$1&$B$2&1),0)-EOMONTH(DATEVALUE($Z$1&$B$2&1),-1)-1),"",H6+1) -> 18 | C7: =IF(OR(B7="",VALUE(B7)>EOMONTH(DATEVALUE($Z$1&$B$2&1),0)-EOMONTH(DATEVALUE($Z$1&$B$2&1),-1)-1),"",B7+1) -> 19 | D7: =IF(OR(C7="",VALUE(C7)>EOMONTH(DATEVALUE($Z$1&$B$2&1),0)-EOMONTH(DATEVALUE($Z$1&$B$2&1),-1)-1),"",C7+1) -> 20 | E7: =IF(OR(D7="",VALUE(D7)>EOMONTH(DATEVALUE($Z$1&$B$2&1),0)-EOMONTH(DATEVALUE($Z$1&$B$2&1),-1)-1),"",D7+1) -> 21 | F7: =IF(OR(E7="",VALUE(E7)>EOMONTH(DATEVALUE($Z$1&$B$2&1),0)-EOMONTH(DATEVALUE($Z$1&$B$2&1),-1)-1),"",E7+1) -> 22 | G7: =IF(OR(F7="",VALUE(F7)>EOMONTH(DATEVALUE($Z$1&$B$2&1),0)-EOMONTH(DATEVALUE($Z$1&$B$2&1),-1)-1),"",F7+1) -> 23 | H7: =IF(OR(G7="",VALUE(G7)>EOMONTH(DATEVALUE($Z$1&$B$2&1),0)-EOMONTH(DATEVALUE($Z$1&$B$2&1),-1)-1),"",G7+1) -> 24 | J7: =IF(OR(P6="",VALUE(P6)>EOMONTH(DATEVALUE($Z$1&$J$2&1),0)-EOMONTH(DATEVALUE($Z$1&$J$2&1),-1)-1),"",P6+1) -> 22 | K7: =IF(OR(J7="",VALUE(J7)>EOMONTH(DATEVALUE($Z$1&$J$2&1),0)-EOMONTH(DATEVALUE($Z$1&$J$2&1),-1)-1),"",J7+1) -> 23 | L7: =IF(OR(K7="",VALUE(K7)>EOMONTH(DATEVALUE($Z$1&$J$2&1),0)-EOMONTH(DATEVALUE($Z$1&$J$2&1),-1)-1),"",K7+1) -> 24 | M7: =IF(OR(L7="",VALUE(L7)>EOMONTH(DATEVALUE($Z$1&$J$2&1),0)-EOMONTH(DATEVALUE($Z$1&$J$2&1),-1)-1),"",L7+1) -> 25 | N7: =IF(OR(M7="",VALUE(M7)>EOMONTH(DATEVALUE($Z$1&$J$2&1),0)-EOMONTH(DATEVALUE($Z$1&$J$2&1),-1)-1),"",M7+1) -> 26 | O7: =IF(OR(N7="",VALUE(N7)>EOMONTH(DATEVALUE($Z$1&$J$2&1),0)-EOMONTH(DATEVALUE($Z$1&$J$2&1),-1)-1),"",N7+1) -> 27 | P7: =IF(OR(O7="",VALUE(O7)>EOMONTH(DATEVALUE($Z$1&$J$2&1),0)-EOMONTH(DATEVALUE($Z$1&$J$2&1),-1)-1),"",O7+1) -> 28 | R7: =IF(OR(X6="",VALUE(X6)>EOMONTH(DATEVALUE($Z$1&$R$2&1),0)-EOMONTH(DATEVALUE($Z$1&$R$2&1),-1)-1),"",X6+1) -> 22 | S7: =IF(OR(R7="",VALUE(R7)>EOMONTH(DATEVALUE($Z$1&$R$2&1),0)-EOMONTH(DATEVALUE($Z$1&$R$2&1),-1)-1),"",R7+1) -> 23 | T7: =IF(OR(S7="",VALUE(S7)>EOMONTH(DATEVALUE($Z$1&$R$2&1),0)-EOMONTH(DATEVALUE($Z$1&$R$2&1),-1)-1),"",S7+1) -> 24 | U7: =IF(OR(T7="",VALUE(T7)>EOMONTH(DATEVALUE($Z$1&$R$2&1),0)-EOMONTH(DATEVALUE($Z$1&$R$2&1),-1)-1),"",T7+1) -> 25 | V7: =IF(OR(U7="",VALUE(U7)>EOMONTH(DATEVALUE($Z$1&$R$2&1),0)-EOMONTH(DATEVALUE($Z$1&$R$2&1),-1)-1),"",U7+1) -> 26 | W7: =IF(OR(V7="",VALUE(V7)>EOMONTH(DATEVALUE($Z$1&$R$2&1),0)-EOMONTH(DATEVALUE($Z$1&$R$2&1),-1)-1),"",V7+1) -> 27 | X7: =IF(OR(W7="",VALUE(W7)>EOMONTH(DATEVALUE($Z$1&$R$2&1),0)-EOMONTH(DATEVALUE($Z$1&$R$2&1),-1)-1),"",W7+1) -> 28
B8: =IF(OR(H7="",VALUE(H7)>EOMONTH(DATEVALUE($Z$1&$B$2&1),0)-EOMONTH(DATEVALUE($Z$1&$B$2&1),-1)-1),"",H7+1) -> 25 | C8: =IF(OR(B8="",VALUE(B8)>EOMONTH(DATEVALUE($Z$1&$B$2&1),0)-EOMONTH(DATEVALUE($Z$1&$B$2&1),-1)-1),"",B8+1) -> 26 | D8: =IF(OR(C8="",VALUE(C8)>EOMONTH(DATEVALUE($Z$1&$B$2&1),0)-EOMONTH(DATEVALUE($Z$1&$B$2&1),-1)-1),"",C8+1) -> 27 | E8: =IF(OR(D8="",VALUE(D8)>EOMONTH(DATEVALUE($Z$1&$B$2&1),0)-EOMONTH(DATEVALUE($Z$1&$B$2&1),-1)-1),"",D8+1) -> 28 | F8: =IF(OR(E8="",VALUE(E8)>EOMONTH(DATEVALUE($Z$1&$B$2&1),0)-EOMONTH(DATEVALUE($Z$1&$B$2&1),-1)-1),"",E8+1) -> 29 | G8: =IF(OR(F8="",VALUE(F8)>EOMONTH(DATEVALUE($Z$1&$B$2&1),0)-EOMONTH(DATEVALUE($Z$1&$B$2&1),-1)-1),"",F8+1) -> 30 | H8: =IF(OR(G8="",VALUE(G8)>EOMONTH(DATEVALUE($Z$1&$B$2&1),0)-EOMONTH(DATEVALUE($Z$1&$B$2&1),-1)-1),"",G8+1) -> 31 | J8: =IF(OR(P7="",VALUE(P7)>EOMONTH(DATEVALUE($Z$1&$J$2&1),0)-EOMONTH(DATEVALUE($Z$1&$J$2&1),-1)-1),"",P7+1) | K8: =IF(OR(J8="",VALUE(J8)>EOMONTH(DATEVALUE($Z$1&$J$2&1),0)-EOMONTH(DATEVALUE($Z$1&$J$2&1),-1)-1),"",J8+1) | L8: =IF(OR(K8="",VALUE(K8)>EOMONTH(DATEVALUE($Z$1&$J$2&1),0)-EOMONTH(DATEVALUE($Z$1&$J$2&1),-1)-1),"",K8+1) | M8: =IF(OR(L8="",VALUE(L8)>EOMONTH(DATEVALUE($Z$1&$J$2&1),0)-EOMONTH(DATEVALUE($Z$1&$J$2&1),-1)-1),"",L8+1) | N8: =IF(OR(M8="",VALUE(M8)>EOMONTH(DATEVALUE($Z$1&$J$2&1),0)-EOMONTH(DATEVALUE($Z$1&$J$2&1),-1)-1),"",M8+1) | O8: =IF(OR(N8="",VALUE(N8)>EOMONTH(DATEVALUE($Z$1&$J$2&1),0)-EOMONTH(DATEVALUE($Z$1&$J$2&1),-1)-1),"",N8+1) | P8: =IF(OR(O8="",VALUE(O8)>EOMONTH(DATEVALUE($Z$1&$J$2&1),0)-EOMONTH(DATEVALUE($Z$1&$J$2&1),-1)-1),"",O8+1) | R8: =IF(OR(X7="",VALUE(X7)>EOMONTH(DATEVALUE($Z$1&$R$2&1),0)-EOMONTH(DATEVALUE($Z$1&$R$2&1),-1)-1),"",X7+1) -> 29 | S8: =IF(OR(R8="",VALUE(R8)>EOMONTH(DATEVALUE($Z$1&$R$2&1),0)-EOMONTH(DATEVALUE($Z$1&$R$2&1),-1)-1),"",R8+1) -> 30 | T8: =IF(OR(S8="",VALUE(S8)>EOMONTH(DATEVALUE($Z$1&$R$2&1),0)-EOMONTH(DATEVALUE($Z$1&$R$2&1),-1)-1),"",S8+1) -> 31 | U8: =IF(OR(T8="",VALUE(T8)>EOMONTH(DATEVALUE($Z$1&$R$2&1),0)-EOMONTH(DATEVALUE($Z$1&$R$2&1),-1)-1),"",T8+1) | V8: =IF(OR(U8="",VALUE(U8)>EOMONTH(DATEVALUE($Z$1&$R$2&1),0)-EOMONTH(DATEVALUE($Z$1&$R$2&1),-1)-1),"",U8+1) | W8: =IF(OR(V8="",VALUE(V8)>EOMONTH(DATEVALUE($Z$1&$R$2&1),0)-EOMONTH(DATEVALUE($Z$1&$R$2&1),-1)-1),"",V8+1) | X8: =IF(OR(W8="",VALUE(W8)>EOMONTH(DATEVALUE($Z$1&$R$2&1),0)-EOMONTH(DATEVALUE($Z$1&$R$2&1),-1)-1),"",W8+1)
B9: =IF(OR(H8="",VALUE(H8)>EOMONTH(DATEVALUE($Z$1&$B$2&1),0)-EOMONTH(DATEVALUE($Z$1&$B$2&1),-1)-1),"",H8+1) | C9: =IF(OR(B9="",VALUE(B9)>EOMONTH(DATEVALUE($Z$1&$B$2&1),0)-EOMONTH(DATEVALUE($Z$1&$B$2&1),-1)-1),"",B9+1) | D9: =IF(OR(C9="",VALUE(C9)>EOMONTH(DATEVALUE($Z$1&$B$2&1),0)-EOMONTH(DATEVALUE($Z$1&$B$2&1),-1)-1),"",C9+1) | E9: =IF(OR(D9="",VALUE(D9)>EOMONTH(DATEVALUE($Z$1&$B$2&1),0)-EOMONTH(DATEVALUE($Z$1&$B$2&1),-1)-1),"",D9+1) | F9: =IF(OR(E9="",VALUE(E9)>EOMONTH(DATEVALUE($Z$1&$B$2&1),0)-EOMONTH(DATEVALUE($Z$1&$B$2&1),-1)-1),"",E9+1) | G9: =IF(OR(F9="",VALUE(F9)>EOMONTH(DATEVALUE($Z$1&$B$2&1),0)-EOMONTH(DATEVALUE($Z$1&$B$2&1),-1)-1),"",F9+1) | H9: =IF(OR(G9="",VALUE(G9)>EOMONTH(DATEVALUE($Z$1&$B$2&1),0)-EOMONTH(DATEVALUE($Z$1&$B$2&1),-1)-1),"",G9+1) | J9: =IF(OR(P8="",VALUE(P8)>EOMONTH(DATEVALUE($Z$1&$J$2&1),0)-EOMONTH(DATEVALUE($Z$1&$J$2&1),-1)-1),"",P8+1) | K9: =IF(OR(J9="",VALUE(J9)>EOMONTH(DATEVALUE($Z$1&$J$2&1),0)-EOMONTH(DATEVALUE($Z$1&$J$2&1),-1)-1),"",J9+1) | L9: =IF(OR(K9="",VALUE(K9)>EOMONTH(DATEVALUE($Z$1&$J$2&1),0)-EOMONTH(DATEVALUE($Z$1&$J$2&1),-1)-1),"",K9+1) | M9: =IF(OR(L9="",VALUE(L9)>EOMONTH(DATEVALUE($Z$1&$J$2&1),0)-EOMONTH(DATEVALUE($Z$1&$J$2&1),-1)-1),"",L9+1) | N9: =IF(OR(M9="",VALUE(M9)>EOMONTH(DATEVALUE($Z$1&$J$2&1),0)-EOMONTH(DATEVALUE($Z$1&$J$2&1),-1)-1),"",M9+1) | O9: =IF(OR(N9="",VALUE(N9)>EOMONTH(DATEVALUE($Z$1&$J$2&1),0)-EOMONTH(DATEVALUE($Z$1&$J$2&1),-1)-1),"",N9+1) | P9: =IF(OR(O9="",VALUE(O9)>EOMONTH(DATEVALUE($Z$1&$J$2&1),0)-EOMONTH(DATEVALUE($Z$1&$J$2&1),-1)-1),"",O9+1) | R9: =IF(OR(X8="",VALUE(X8)>EOMONTH(DATEVALUE($Z$1&$R$2&1),0)-EOMONTH(DATEVALUE($Z$1&$R$2&1),-1)-1),"",X8+1) | S9: =IF(OR(R9="",VALUE(R9)>EOMONTH(DATEVALUE($Z$1&$R$2&1),0)-EOMONTH(DATEVALUE($Z$1&$R$2&1),-1)-1),"",R9+1) | T9: =IF(OR(S9="",VALUE(S9)>EOMONTH(DATEVALUE($Z$1&$R$2&1),0)-EOMONTH(DATEVALUE($Z$1&$R$2&1),-1)-1),"",S9+1) | U9: =IF(OR(T9="",VALUE(T9)>EOMONTH(DATEVALUE($Z$1&$R$2&1),0)-EOMONTH(DATEVALUE($Z$1&$R$2&1),-1)-1),"",T9+1) | V9: =IF(OR(U9="",VALUE(U9)>EOMONTH(DATEVALUE($Z$1&$R$2&1),0)-EOMONTH(DATEVALUE($Z$1&$R$2&1),-1)-1),"",U9+1) | W9: =IF(OR(V9="",VALUE(V9)>EOMONTH(DATEVALUE($Z$1&$R$2&1),0)-EOMONTH(DATEVALUE($Z$1&$R$2&1),-1)-1),"",V9+1) | X9: =IF(OR(W9="",VALUE(W9)>EOMONTH(DATEVALUE($Z$1&$R$2&1),0)-EOMONTH(DATEVALUE($Z$1&$R$2&1),-1)-1),"",W9+1)
B11: APRIL | J11: MAY | R11: JUNE
B12: S | C12: M | D12: T | E12: W | F12: T | G12: F | H12: S | J12: S | K12: M | L12: T | M12: W | N12: T | O12: F | P12: S | R12: S | S12: M | T12: T | U12: W | V12: T | W12: F | X12: S
B13: =IF(WEEKDAY(DATEVALUE($Z$1&$B$11&1))=1,1,"") | C13: =IF(B13<>"",B13+1,IF(WEEKDAY(DATEVALUE($Z$1&$B$11&1))=2,1,"")) | D13: =IF(C13<>"",C13+1,IF(WEEKDAY(DATEVALUE($Z$1&$B$11&1))=3,1,"")) | E13: =IF(D13<>"",D13+1,IF(WEEKDAY(DATEVALUE($Z$1&$B$11&1))=4,1,"")) -> 1 | F13: =IF(E13<>"",E13+1,IF(WEEKDAY(DATEVALUE($Z$1&$B$11&1))=5,1,"")) -> 2 | G13: =IF(F13<>"",F13+1,IF(WEEKDAY(DATEVALUE($Z$1&$B$11&1))=6,1,"")) -> 3 | H13: =IF(G13<>"",G13+1,IF(WEEKDAY(DATEVALUE($Z$1&$B$11&1))=7,1,"")) -> 4 | J13: =IF(WEEKDAY(DATEVALUE($Z$1&$J$11&1))=1,1,"") | K13: =IF(J13<>"",J13+1,IF(WEEKDAY(DATEVALUE($Z$1&$J$11&1))=2,1,"")) | L13: =IF(K13<>"",K13+1,IF(WEEKDAY(DATEVALUE($Z$1&$J$11&1))=3,1,"")) | M13: =IF(L13<>"",L13+1,IF(WEEKDAY(DATEVALUE($Z$1&$J$11&1))=4,1,"")) | N13: =IF(M13<>"",M13+1,IF(WEEKDAY(DATEVALUE($Z$1&$J$11&1))=5,1,"")) | O13: =IF(N13<>"",N13+1,IF(WEEKDAY(DATEVALUE($Z$1&$J$11&1))=6,1,"")) -> 1 | P13: =IF(O13<>"",O13+1,IF(WEEKDAY(DATEVALUE($Z$1&$J$11&1))=7,1,"")) -> 2 | R13: =IF(WEEKDAY(DATEVALUE($Z$1&$R$11&1))=1,1,"") | S13: =IF(R13<>"",R13+1,IF(WEEKDAY(DATEVALUE($Z$1&$R$11&1))=2,1,"")) -> 1 | T13: =IF(S13<>"",S13+1,IF(WEEKDAY(DATEVALUE($Z$1&$R$11&1))=3,1,"")) -> 2 | U13: =IF(T13<>"",T13+1,IF(WEEKDAY(DATEVALUE($Z$1&$R$11&1))=4,1,"")) -> 3 | V13: =IF(U13<>"",U13+1,IF(WEEKDAY(DATEVALUE($Z$1&$R$11&1))=5,1,"")) -> 4 | W13: =IF(V13<>"",V13+1,IF(WEEKDAY(DATEVALUE($Z$1&$R$11&1))=6,1,"")) -> 5 | X13: =IF(W13<>"",W13+1,IF(WEEKDAY(DATEVALUE($Z$1&$R$11&1))=7,1,"")) -> 6
B14: =IF(OR(H13="",VALUE(H13)>EOMONTH(DATEVALUE($Z$1&$B$11&1),0)-EOMONTH(DATEVALUE($Z$1&$B$11&1),-1)-1),"",H13+1) -> 5 | C14: =IF(OR(B14="",VALUE(B14)>EOMONTH(DATEVALUE($Z$1&$B$11&1),0)-EOMONTH(DATEVALUE($Z$1&$B$11&1),-1)-1),"",B14+1) -> 6 | D14: =IF(OR(C14="",VALUE(C14)>EOMONTH(DATEVALUE($Z$1&$B$11&1),0)-EOMONTH(DATEVALUE($Z$1&$B$11&1),-1)-1),"",C14+1) -> 7 | E14: =IF(OR(D14="",VALUE(D14)>EOMONTH(DATEVALUE($Z$1&$B$11&1),0)-EOMONTH(DATEVALUE($Z$1&$B$11&1),-1)-1),"",D14+1) -> 8 | F14: =IF(OR(E14="",VALUE(E14)>EOMONTH(DATEVALUE($Z$1&$B$11&1),0)-EOMONTH(DATEVALUE($Z$1&$B$11&1),-1)-1),"",E14+1) -> 9 | G14: =IF(OR(F14="",VALUE(F14)>EOMONTH(DATEVALUE($Z$1&$B$11&1),0)-EOMONTH(DATEVALUE($Z$1&$B$11&1),-1)-1),"",F14+1) -> 10 | H14: =IF(OR(G14="",VALUE(G14)>EOMONTH(DATEVALUE($Z$1&$B$11&1),0)-EOMONTH(DATEVALUE($Z$1&$B$11&1),-1)-1),"",G14+1) -> 11 | J14: =IF(OR(P13="",VALUE(P13)>EOMONTH(DATEVALUE($Z$1&$J$11&1),0)-EOMONTH(DATEVALUE($Z$1&$J$11&1),-1)-1),"",P13+1) -> 3 | K14: =IF(OR(J14="",VALUE(J14)>EOMONTH(DATEVALUE($Z$1&$J$11&1),0)-EOMONTH(DATEVALUE($Z$1&$J$11&1),-1)-1),"",J14+1) -> 4 | L14: =IF(OR(K14="",VALUE(K14)>EOMONTH(DATEVALUE($Z$1&$J$11&1),0)-EOMONTH(DATEVALUE($Z$1&$J$11&1),-1)-1),"",K14+1) -> 5 | M14: =IF(OR(L14="",VALUE(L14)>EOMONTH(DATEVALUE($Z$1&$J$11&1),0)-EOMONTH(DATEVALUE($Z$1&$J$11&1),-1)-1),"",L14+1) -> 6 | N14: =IF(OR(M14="",VALUE(M14)>EOMONTH(DATEVALUE($Z$1&$J$11&1),0)-EOMONTH(DATEVALUE($Z$1&$J$11&1),-1)-1),"",M14+1) -> 7 | O14: =IF(OR(N14="",VALUE(N14)>EOMONTH(DATEVALUE($Z$1&$J$11&1),0)-EOMONTH(DATEVALUE($Z$1&$J$11&1),-1)-1),"",N14+1) -> 8 | P14: =IF(OR(O14="",VALUE(O14)>EOMONTH(DATEVALUE($Z$1&$J$11&1),0)-EOMONTH(DATEVALUE($Z$1&$J$11&1),-1)-1),"",O14+1) -> 9 | R14: =IF(OR(X13="",VALUE(X13)>EOMONTH(DATEVALUE($Z$1&$R$11&1),0)-EOMONTH(DATEVALUE($Z$1&$R$11&1),-1)-1),"",X13+1) -> 7 | S14: =IF(OR(R14="",VALUE(R14)>EOMONTH(DATEVALUE($Z$1&$R$11&1),0)-EOMONTH(DATEVALUE($Z$1&$R$11&1),-1)-1),"",R14+1) -> 8 | T14: =IF(OR(S14="",VALUE(S14)>EOMONTH(DATEVALUE($Z$1&$R$11&1),0)-EOMONTH(DATEVALUE($Z$1&$R$11&1),-1)-1),"",S14+1) -> 9 | U14: =IF(OR(T14="",VALUE(T14)>EOMONTH(DATEVALUE($Z$1&$R$11&1),0)-EOMONTH(DATEVALUE($Z$1&$R$11&1),-1)-1),"",T14+1) -> 10 | V14: =IF(OR(U14="",VALUE(U14)>EOMONTH(DATEVALUE($Z$1&$R$11&1),0)-EOMONTH(DATEVALUE($Z$1&$R$11&1),-1)-1),"",U14+1) -> 11 | W14: =IF(OR(V14="",VALUE(V14)>EOMONTH(DATEVALUE($Z$1&$R$11&1),0)-EOMONTH(DATEVALUE($Z$1&$R$11&1),-1)-1),"",V14+1) -> 12 | X14: =IF(OR(W14="",VALUE(W14)>EOMONTH(DATEVALUE($Z$1&$R$11&1),0)-EOMONTH(DATEVALUE($Z$1&$R$11&1),-1)-1),"",W14+1) -> 13
B15: =IF(OR(H14="",VALUE(H14)>EOMONTH(DATEVALUE($Z$1&$B$11&1),0)-EOMONTH(DATEVALUE($Z$1&$B$11&1),-1)-1),"",H14+1) -> 12 | C15: =IF(OR(B15="",VALUE(B15)>EOMONTH(DATEVALUE($Z$1&$B$11&1),0)-EOMONTH(DATEVALUE($Z$1&$B$11&1),-1)-1),"",B15+1) -> 13 | D15: =IF(OR(C15="",VALUE(C15)>EOMONTH(DATEVALUE($Z$1&$B$11&1),0)-EOMONTH(DATEVALUE($Z$1&$B$11&1),-1)-1),"",C15+1) -> 14 | E15: =IF(OR(D15="",VALUE(D15)>EOMONTH(DATEVALUE($Z$1&$B$11&1),0)-EOMONTH(DATEVALUE($Z$1&$B$11&1),-1)-1),"",D15+1) -> 15 | F15: =IF(OR(E15="",VALUE(E15)>EOMONTH(DATEVALUE($Z$1&$B$11&1),0)-EOMONTH(DATEVALUE($Z$1&$B$11&1),-1)-1),"",E15+1) -> 16 | G15: =IF(OR(F15="",VALUE(F15)>EOMONTH(DATEVALUE($Z$1&$B$11&1),0)-EOMONTH(DATEVALUE($Z$1&$B$11&1),-1)-1),"",F15+1) -> 17 | H15: =IF(OR(G15="",VALUE(G15)>EOMONTH(DATEVALUE($Z$1&$B$11&1),0)-EOMONTH(DATEVALUE($Z$1&$B$11&1),-1)-1),"",G15+1) -> 18 | J15: =IF(OR(P14="",VALUE(P14)>EOMONTH(DATEVALUE($Z$1&$J$11&1),0)-EOMONTH(DATEVALUE($Z$1&$J$11&1),-1)-1),"",P14+1) -> 10 | K15: =IF(OR(J15="",VALUE(J15)>EOMONTH(DATEVALUE($Z$1&$J$11&1),0)-EOMONTH(DATEVALUE($Z$1&$J$11&1),-1)-1),"",J15+1) -> 11 | L15: =IF(OR(K15="",VALUE(K15)>EOMONTH(DATEVALUE($Z$1&$J$11&1),0)-EOMONTH(DATEVALUE($Z$1&$J$11&1),-1)-1),"",K15+1) -> 12 | M15: =IF(OR(L15="",VALUE(L15)>EOMONTH(DATEVALUE($Z$1&$J$11&1),0)-EOMONTH(DATEVALUE($Z$1&$J$11&1),-1)-1),"",L15+1) -> 13 | N15: =IF(OR(M15="",VALUE(M15)>EOMONTH(DATEVALUE($Z$1&$J$11&1),0)-EOMONTH(DATEVALUE($Z$1&$J$11&1),-1)-1),"",M15+1) -> 14 | O15: =IF(OR(N15="",VALUE(N15)>EOMONTH(DATEVALUE($Z$1&$J$11&1),0)-EOMONTH(DATEVALUE($Z$1&$J$11&1),-1)-1),"",N15+1) -> 15 | P15: =IF(OR(O15="",VALUE(O15)>EOMONTH(DATEVALUE($Z$1&$J$11&1),0)-EOMONTH(DATEVALUE($Z$1&$J$11&1),-1)-1),"",O15+1) -> 16 | R15: =IF(OR(X14="",VALUE(X14)>EOMONTH(DATEVALUE($Z$1&$R$11&1),0)-EOMONTH(DATEVALUE($Z$1&$R$11&1),-1)-1),"",X14+1) -> 14 | S15: =IF(OR(R15="",VALUE(R15)>EOMONTH(DATEVALUE($Z$1&$R$11&1),0)-EOMONTH(DATEVALUE($Z$1&$R$11&1),-1)-1),"",R15+1) -> 15 | T15: =IF(OR(S15="",VALUE(S15)>EOMONTH(DATEVALUE($Z$1&$R$11&1),0)-EOMONTH(DATEVALUE($Z$1&$R$11&1),-1)-1),"",S15+1) -> 16 | U15: =IF(OR(T15="",VALUE(T15)>EOMONTH(DATEVALUE($Z$1&$R$11&1),0)-EOMONTH(DATEVALUE($Z$1&$R$11&1),-1)-1),"",T15+1) -> 17 | V15: =IF(OR(U15="",VALUE(U15)>EOMONTH(DATEVALUE($Z$1&$R$11&1),0)-EOMONTH(DATEVALUE($Z$1&$R$11&1),-1)-1),"",U15+1) -> 18 | W15: =IF(OR(V15="",VALUE(V15)>EOMONTH(DATEVALUE($Z$1&$R$11&1),0)-EOMONTH(DATEVALUE($Z$1&$R$11&1),-1)-1),"",V15+1) -> 19 | X15: =IF(OR(W15="",VALUE(W15)>EOMONTH(DATEVALUE($Z$1&$R$11&1),0)-EOMONTH(DATEVALUE($Z$1&$R$11&1),-1)-1),"",W15+1) -> 20
B16: =IF(OR(H15="",VALUE(H15)>EOMONTH(DATEVALUE($Z$1&$B$11&1),0)-EOMONTH(DATEVALUE($Z$1&$B$11&1),-1)-1),"",H15+1) -> 19 | C16: =IF(OR(B16="",VALUE(B16)>EOMONTH(DATEVALUE($Z$1&$B$11&1),0)-EOMONTH(DATEVALUE($Z$1&$B$11&1),-1)-1),"",B16+1) -> 20 | D16: =IF(OR(C16="",VALUE(C16)>EOMONTH(DATEVALUE($Z$1&$B$11&1),0)-EOMONTH(DATEVALUE($Z$1&$B$11&1),-1)-1),"",C16+1) -> 21 | E16: =IF(OR(D16="",VALUE(D16)>EOMONTH(DATEVALUE($Z$1&$B$11&1),0)-EOMONTH(DATEVALUE($Z$1&$B$11&1),-1)-1),"",D16+1) -> 22 | F16: =IF(OR(E16="",VALUE(E16)>EOMONTH(DATEVALUE($Z$1&$B$11&1),0)-EOMONTH(DATEVALUE($Z$1&$B$11&1),-1)-1),"",E16+1) -> 23 | G16: =IF(OR(F16="",VALUE(F16)>EOMONTH(DATEVALUE($Z$1&$B$11&1),0)-EOMONTH(DATEVALUE($Z$1&$B$11&1),-1)-1),"",F16+1) -> 24 | H16: =IF(OR(G16="",VALUE(G16)>EOMONTH(DATEVALUE($Z$1&$B$11&1),0)-EOMONTH(DATEVALUE($Z$1&$B$11&1),-1)-1),"",G16+1) -> 25 | J16: =IF(OR(P15="",VALUE(P15)>EOMONTH(DATEVALUE($Z$1&$J$11&1),0)-EOMONTH(DATEVALUE($Z$1&$J$11&1),-1)-1),"",P15+1) -> 17 | K16: =IF(OR(J16="",VALUE(J16)>EOMONTH(DATEVALUE($Z$1&$J$11&1),0)-EOMONTH(DATEVALUE($Z$1&$J$11&1),-1)-1),"",J16+1) -> 18 | L16: =IF(OR(K16="",VALUE(K16)>EOMONTH(DATEVALUE($Z$1&$J$11&1),0)-EOMONTH(DATEVALUE($Z$1&$J$11&1),-1)-1),"",K16+1) -> 19 | M16: =IF(OR(L16="",VALUE(L16)>EOMONTH(DATEVALUE($Z$1&$J$11&1),0)-EOMONTH(DATEVALUE($Z$1&$J$11&1),-1)-1),"",L16+1) -> 20 | N16: =IF(OR(M16="",VALUE(M16)>EOMONTH(DATEVALUE($Z$1&$J$11&1),0)-EOMONTH(DATEVALUE($Z$1&$J$11&1),-1)-1),"",M16+1) -> 21 | O16: =IF(OR(N16="",VALUE(N16)>EOMONTH(DATEVALUE($Z$1&$J$11&1),0)-EOMONTH(DATEVALUE($Z$1&$J$11&1),-1)-1),"",N16+1) -> 22 | P16: =IF(OR(O16="",VALUE(O16)>EOMONTH(DATEVALUE($Z$1&$J$11&1),0)-EOMONTH(DATEVALUE($Z$1&$J$11&1),-1)-1),"",O16+1) -> 23 | R16: =IF(OR(X15="",VALUE(X15)>EOMONTH(DATEVALUE($Z$1&$R$11&1),0)-EOMONTH(DATEVALUE($Z$1&$R$11&1),-1)-1),"",X15+1) -> 21 | S16: =IF(OR(R16="",VALUE(R16)>EOMONTH(DATEVALUE($Z$1&$R$11&1),0)-EOMONTH(DATEVALUE($Z$1&$R$11&1),-1)-1),"",R16+1) -> 22 | T16: =IF(OR(S16="",VALUE(S16)>EOMONTH(DATEVALUE($Z$1&$R$11&1),0)-EOMONTH(DATEVALUE($Z$1&$R$11&1),-1)-1),"",S16+1) -> 23 | U16: =IF(OR(T16="",VALUE(T16)>EOMONTH(DATEVALUE($Z$1&$R$11&1),0)-EOMONTH(DATEVALUE($Z$1&$R$11&1),-1)-1),"",T16+1) -> 24 | V16: =IF(OR(U16="",VALUE(U16)>EOMONTH(DATEVALUE($Z$1&$R$11&1),0)-EOMONTH(DATEVALUE($Z$1&$R$11&1),-1)-1),"",U16+1) -> 25 | W16: =IF(OR(V16="",VALUE(V16)>EOMONTH(DATEVALUE($Z$1&$R$11&1),0)-EOMONTH(DATEVALUE($Z$1&$R$11&1),-1)-1),"",V16+1) -> 26 | X16: =IF(OR(W16="",VALUE(W16)>EOMONTH(DATEVALUE($Z$1&$R$11&1),0)-EOMONTH(DATEVALUE($Z$1&$R$11&1),-1)-1),"",W16+1) -> 27
B17: =IF(OR(H16="",VALUE(H16)>EOMONTH(DATEVALUE($Z$1&$B$11&1),0)-EOMONTH(DATEVALUE($Z$1&$B$11&1),-1)-1),"",H16+1) -> 26 | C17: =IF(OR(B17="",VALUE(B17)>EOMONTH(DATEVALUE($Z$1&$B$11&1),0)-EOMONTH(DATEVALUE($Z$1&$B$11&1),-1)-1),"",B17+1) -> 27 | D17: =IF(OR(C17="",VALUE(C17)>EOMONTH(DATEVALUE($Z$1&$B$11&1),0)-EOMONTH(DATEVALUE($Z$1&$B$11&1),-1)-1),"",C17+1) -> 28 | E17: =IF(OR(D17="",VALUE(D17)>EOMONTH(DATEVALUE($Z$1&$B$11&1),0)-EOMONTH(DATEVALUE($Z$1&$B$11&1),-1)-1),"",D17+1) -> 29 | F17: =IF(OR(E17="",VALUE(E17)>EOMONTH(DATEVALUE($Z$1&$B$11&1),0)-EOMONTH(DATEVALUE($Z$1&$B$11&1),-1)-1),"",E17+1) -> 30 | G17: =IF(OR(F17="",VALUE(F17)>EOMONTH(DATEVALUE($Z$1&$B$11&1),0)-EOMONTH(DATEVALUE($Z$1&$B$11&1),-1)-1),"",F17+1) | H17: =IF(OR(G17="",VALUE(G17)>EOMONTH(DATEVALUE($Z$1&$B$11&1),0)-EOMONTH(DATEVALUE($Z$1&$B$11&1),-1)-1),"",G17+1) | J17: =IF(OR(P16="",VALUE(P16)>EOMONTH(DATEVALUE($Z$1&$J$11&1),0)-EOMONTH(DATEVALUE($Z$1&$J$11&1),-1)-1),"",P16+1) -> 24 | K17: =IF(OR(J17="",VALUE(J17)>EOMONTH(DATEVALUE($Z$1&$J$11&1),0)-EOMONTH(DATEVALUE($Z$1&$J$11&1),-1)-1),"",J17+1) -> 25 | L17: =IF(OR(K17="",VALUE(K17)>EOMONTH(DATEVALUE($Z$1&$J$11&1),0)-EOMONTH(DATEVALUE($Z$1&$J$11&1),-1)-1),"",K17+1) -> 26 | M17: =IF(OR(L17="",VALUE(L17)>EOMONTH(DATEVALUE($Z$1&$J$11&1),0)-EOMONTH(DATEVALUE($Z$1&$J$11&1),-1)-1),"",L17+1) -> 27 | N17: =IF(OR(M17="",VALUE(M17)>EOMONTH(DATEVALUE($Z$1&$J$11&1),0)-EOMONTH(DATEVALUE($Z$1&$J$11&1),-1)-1),"",M17+1) -> 28 | O17: =IF(OR(N17="",VALUE(N17)>EOMONTH(DATEVALUE($Z$1&$J$11&1),0)-EOMONTH(DATEVALUE($Z$1&$J$11&1),-1)-1),"",N17+1) -> 29 | P17: =IF(OR(O17="",VALUE(O17)>EOMONTH(DATEVALUE($Z$1&$J$11&1),0)-EOMONTH(DATEVALUE($Z$1&$J$11&1),-1)-1),"",O17+1) -> 30 | R17: =IF(OR(X16="",VALUE(X16)>EOMONTH(DATEVALUE($Z$1&$R$11&1),0)-EOMONTH(DATEVALUE($Z$1&$R$11&1),-1)-1),"",X16+1) -> 28 | S17: =IF(OR(R17="",VALUE(R17)>EOMONTH(DATEVALUE($Z$1&$R$11&1),0)-EOMONTH(DATEVALUE($Z$1&$R$11&1),-1)-1),"",R17+1) -> 29 | T17: =IF(OR(S17="",VALUE(S17)>EOMONTH(DATEVALUE($Z$1&$R$11&1),0)-EOMONTH(DATEVALUE($Z$1&$R$11&1),-1)-1),"",S17+1) -> 30 | U17: =IF(OR(T17="",VALUE(T17)>EOMONTH(DATEVALUE($Z$1&$R$11&1),0)-EOMONTH(DATEVALUE($Z$1&$R$11&1),-1)-1),"",T17+1) | V17: =IF(OR(U17="",VALUE(U17)>EOMONTH(DATEVALUE($Z$1&$R$11&1),0)-EOMONTH(DATEVALUE($Z$1&$R$11&1),-1)-1),"",U17+1) | W17: =IF(OR(V17="",VALUE(V17)>EOMONTH(DATEVALUE($Z$1&$R$11&1),0)-EOMONTH(DATEVALUE($Z$1&$R$11&1),-1)-1),"",V17+1) | X17: =IF(OR(W17="",VALUE(W17)>EOMONTH(DATEVALUE($Z$1&$R$11&1),0)-EOMONTH(DATEVALUE($Z$1&$R$11&1),-1)-1),"",W17+1)
B18: =IF(OR(H17="",VALUE(H17)>EOMONTH(DATEVALUE($Z$1&$B$11&1),0)-EOMONTH(DATEVALUE($Z$1&$B$11&1),-1)-1),"",H17+1) | C18: =IF(OR(B18="",VALUE(B18)>EOMONTH(DATEVALUE($Z$1&$B$11&1),0)-EOMONTH(DATEVALUE($Z$1&$B$11&1),-1)-1),"",B18+1) | D18: =IF(OR(C18="",VALUE(C18)>EOMONTH(DATEVALUE($Z$1&$B$11&1),0)-EOMONTH(DATEVALUE($Z$1&$B$11&1),-1)-1),"",C18+1) | E18: =IF(OR(D18="",VALUE(D18)>EOMONTH(DATEVALUE($Z$1&$B$11&1),0)-EOMONTH(DATEVALUE($Z$1&$B$11&1),-1)-1),"",D18+1) | F18: =IF(OR(E18="",VALUE(E18)>EOMONTH(DATEVALUE($Z$1&$B$11&1),0)-EOMONTH(DATEVALUE($Z$1&$B$11&1),-1)-1),"",E18+1) | G18: =IF(OR(F18="",VALUE(F18)>EOMONTH(DATEVALUE($Z$1&$B$11&1),0)-EOMONTH(DATEVALUE($Z$1&$B$11&1),-1)-1),"",F18+1) | H18: =IF(OR(G18="",VALUE(G18)>EOMONTH(DATEVALUE($Z$1&$B$11&1),0)-EOMONTH(DATEVALUE($Z$1&$B$11&1),-1)-1),"",G18+1) | J18: =IF(OR(P17="",VALUE(P17)>EOMONTH(DATEVALUE($Z$1&$J$11&1),0)-EOMONTH(DATEVALUE($Z$1&$J$11&1),-1)-1),"",P17+1) -> 31 | K18: =IF(OR(J18="",VALUE(J18)>EOMONTH(DATEVALUE($Z$1&$J$11&1),0)-EOMONTH(DATEVALUE($Z$1&$J$11&1),-1)-1),"",J18+1) | L18: =IF(OR(K18="",VALUE(K18)>EOMONTH(DATEVALUE($Z$1&$J$11&1),0)-EOMONTH(DATEVALUE($Z$1&$J$11&1),-1)-1),"",K18+1) | M18: =IF(OR(L18="",VALUE(L18)>EOMONTH(DATEVALUE($Z$1&$J$11&1),0)-EOMONTH(DATEVALUE($Z$1&$J$11&1),-1)-1),"",L18+1) | N18: =IF(OR(M18="",VALUE(M18)>EOMONTH(DATEVALUE($Z$1&$J$11&1),0)-EOMONTH(DATEVALUE($Z$1&$J$11&1),-1)-1),"",M18+1) | O18: =IF(OR(N18="",VALUE(N18)>EOMONTH(DATEVALUE($Z$1&$J$11&1),0)-EOMONTH(DATEVALUE($Z$1&$J$11&1),-1)-1),"",N18+1) | P18: =IF(OR(O18="",VALUE(O18)>EOMONTH(DATEVALUE($Z$1&$J$11&1),0)-EOMONTH(DATEVALUE($Z$1&$J$11&1),-1)-1),"",O18+1) | R18: =IF(OR(X17="",VALUE(X17)>EOMONTH(DATEVALUE($Z$1&$R$11&1),0)-EOMONTH(DATEVALUE($Z$1&$R$11&1),-1)-1),"",X17+1) | S18: =IF(OR(R18="",VALUE(R18)>EOMONTH(DATEVALUE($Z$1&$R$11&1),0)-EOMONTH(DATEVALUE($Z$1&$R$11&1),-1)-1),"",R18+1) | T18: =IF(OR(S18="",VALUE(S18)>EOMONTH(DATEVALUE($Z$1&$R$11&1),0)-EOMONTH(DATEVALUE($Z$1&$R$11&1),-1)-1),"",S18+1) | U18: =IF(OR(T18="",VALUE(T18)>EOMONTH(DATEVALUE($Z$1&$R$11&1),0)-EOMONTH(DATEVALUE($Z$1&$R$11&1),-1)-1),"",T18+1) | V18: =IF(OR(U18="",VALUE(U18)>EOMONTH(DATEVALUE($Z$1&$R$11&1),0)-EOMONTH(DATEVALUE($Z$1&$R$11&1),-1)-1),"",U18+1) | W18: =IF(OR(V18="",VALUE(V18)>EOMONTH(DATEVALUE($Z$1&$R$11&1),0)-EOMONTH(DATEVALUE($Z$1&$R$11&1),-1)-1),"",V18+1) | X18: =IF(OR(W18="",VALUE(W18)>EOMONTH(DATEVALUE($Z$1&$R$11&1),0)-EOMONTH(DATEVALUE($Z$1&$R$11&1),-1)-1),"",W18+1)
B20: JULY | J20: AUGUST | R20: SEPTEMBER
B21: S | C21: M | D21: T | E21: W | F21: T | G21: F | H21: S | J21: S | K21: M | L21: T | M21: W | N21: T | O21: F | P21: S | R21: S | S21: M | T21: T | U21: W | V21: T | W21: F | X21: S
B22: =IF(WEEKDAY(DATEVALUE($Z$1&$B$20&1))=1,1,"") | C22: =IF(B22<>"",B22+1,IF(WEEKDAY(DATEVALUE($Z$1&$B$20&1))=2,1,"")) | D22: =IF(C22<>"",C22+1,IF(WEEKDAY(DATEVALUE($Z$1&$B$20&1))=3,1,"")) | E22: =IF(D22<>"",D22+1,IF(WEEKDAY(DATEVALUE($Z$1&$B$20&1))=4,1,"")) -> 1 | F22: =IF(E22<>"",E22+1,IF(WEEKDAY(DATEVALUE($Z$1&$B$20&1))=5,1,"")) -> 2 | G22: =IF(F22<>"",F22+1,IF(WEEKDAY(DATEVALUE($Z$1&$B$20&1))=6,1,"")) -> 3 | H22: =IF(G22<>"",G22+1,IF(WEEKDAY(DATEVALUE($Z$1&$B$20&1))=7,1,"")) -> 4 | J22: =IF(WEEKDAY(DATEVALUE($Z$1&$J$20&1))=1,1,"") | K22: =IF(J22<>"",J22+1,IF(WEEKDAY(DATEVALUE($Z$1&$J$20&1))=2,1,"")) | L22: =IF(K22<>"",K22+1,IF(WEEKDAY(DATEVALUE($Z$1&$J$20&1))=3,1,"")) | M22: =IF(L22<>"",L22+1,IF(WEEKDAY(DATEVALUE($Z$1&$J$20&1))=4,1,"")) | N22: =IF(M22<>"",M22+1,IF(WEEKDAY(DATEVALUE($Z$1&$J$20&1))=5,1,"")) | O22: =IF(N22<>"",N22+1,IF(WEEKDAY(DATEVALUE($Z$1&$J$20&1))=6,1,"")) | P22: =IF(O22<>"",O22+1,IF(WEEKDAY(DATEVALUE($Z$1&$J$20&1))=7,1,"")) -> 1 | R22: =IF(WEEKDAY(DATEVALUE($Z$1&$R$20&1))=1,1,"") | S22: =IF(R22<>"",R22+1,IF(WEEKDAY(DATEVALUE($Z$1&$R$20&1))=2,1,"")) | T22: =IF(S22<>"",S22+1,IF(WEEKDAY(DATEVALUE($Z$1&$R$20&1))=3,1,"")) -> 1 | U22: =IF(T22<>"",T22+1,IF(WEEKDAY(DATEVALUE($Z$1&$R$20&1))=4,1,"")) -> 2 | V22: =IF(U22<>"",U22+1,IF(WEEKDAY(DATEVALUE($Z$1&$R$20&1))=5,1,"")) -> 3 | W22: =IF(V22<>"",V22+1,IF(WEEKDAY(DATEVALUE($Z$1&$R$20&1))=6,1,"")) -> 4 | X22: =IF(W22<>"",W22+1,IF(WEEKDAY(DATEVALUE($Z$1&$R$20&1))=7,1,"")) -> 5
B23: =IF(OR(H22="",VALUE(H22)>EOMONTH(DATEVALUE($Z$1&$B$20&1),0)-EOMONTH(DATEVALUE($Z$1&$B$20&1),-1)-1),"",H22+1) -> 5 | C23: =IF(OR(B23="",VALUE(B23)>EOMONTH(DATEVALUE($Z$1&$B$20&1),0)-EOMONTH(DATEVALUE($Z$1&$B$20&1),-1)-1),"",B23+1) -> 6 | D23: =IF(OR(C23="",VALUE(C23)>EOMONTH(DATEVALUE($Z$1&$B$20&1),0)-EOMONTH(DATEVALUE($Z$1&$B$20&1),-1)-1),"",C23+1) -> 7 | E23: =IF(OR(D23="",VALUE(D23)>EOMONTH(DATEVALUE($Z$1&$B$20&1),0)-EOMONTH(DATEVALUE($Z$1&$B$20&1),-1)-1),"",D23+1) -> 8 | F23: =IF(OR(E23="",VALUE(E23)>EOMONTH(DATEVALUE($Z$1&$B$20&1),0)-EOMONTH(DATEVALUE($Z$1&$B$20&1),-1)-1),"",E23+1) -> 9 | G23: =IF(OR(F23="",VALUE(F23)>EOMONTH(DATEVALUE($Z$1&$B$20&1),0)-EOMONTH(DATEVALUE($Z$1&$B$20&1),-1)-1),"",F23+1) -> 10 | H23: =IF(OR(G23="",VALUE(G23)>EOMONTH(DATEVALUE($Z$1&$B$20&1),0)-EOMONTH(DATEVALUE($Z$1&$B$20&1),-1)-1),"",G23+1) -> 11 | J23: =IF(OR(P22="",VALUE(P22)>EOMONTH(DATEVALUE($Z$1&$J$20&1),0)-EOMONTH(DATEVALUE($Z$1&$J$20&1),-1)-1),"",P22+1) -> 2 | K23: =IF(OR(J23="",VALUE(J23)>EOMONTH(DATEVALUE($Z$1&$J$20&1),0)-EOMONTH(DATEVALUE($Z$1&$J$20&1),-1)-1),"",J23+1) -> 3 | L23: =IF(OR(K23="",VALUE(K23)>EOMONTH(DATEVALUE($Z$1&$J$20&1),0)-EOMONTH(DATEVALUE($Z$1&$J$20&1),-1)-1),"",K23+1) -> 4 | M23: =IF(OR(L23="",VALUE(L23)>EOMONTH(DATEVALUE($Z$1&$J$20&1),0)-EOMONTH(DATEVALUE($Z$1&$J$20&1),-1)-1),"",L23+1) -> 5 | N23: =IF(OR(M23="",VALUE(M23)>EOMONTH(DATEVALUE($Z$1&$J$20&1),0)-EOMONTH(DATEVALUE($Z$1&$J$20&1),-1)-1),"",M23+1) -> 6 | O23: =IF(OR(N23="",VALUE(N23)>EOMONTH(DATEVALUE($Z$1&$J$20&1),0)-EOMONTH(DATEVALUE($Z$1&$J$20&1),-1)-1),"",N23+1) -> 7 | P23: =IF(OR(O23="",VALUE(O23)>EOMONTH(DATEVALUE($Z$1&$J$20&1),0)-EOMONTH(DATEVALUE($Z$1&$J$20&1),-1)-1),"",O23+1) -> 8 | R23: =IF(OR(X22="",VALUE(X22)>EOMONTH(DATEVALUE($Z$1&$R$20&1),0)-EOMONTH(DATEVALUE($Z$1&$R$20&1),-1)-1),"",X22+1) -> 6 | S23: =IF(OR(R23="",VALUE(R23)>EOMONTH(DATEVALUE($Z$1&$R$20&1),0)-EOMONTH(DATEVALUE($Z$1&$R$20&1),-1)-1),"",R23+1) -> 7 | T23: =IF(OR(S23="",VALUE(S23)>EOMONTH(DATEVALUE($Z$1&$R$20&1),0)-EOMONTH(DATEVALUE($Z$1&$R$20&1),-1)-1),"",S23+1) -> 8 | U23: =IF(OR(T23="",VALUE(T23)>EOMONTH(DATEVALUE($Z$1&$R$20&1),0)-EOMONTH(DATEVALUE($Z$1&$R$20&1),-1)-1),"",T23+1) -> 9 | V23: =IF(OR(U23="",VALUE(U23)>EOMONTH(DATEVALUE($Z$1&$R$20&1),0)-EOMONTH(DATEVALUE($Z$1&$R$20&1),-1)-1),"",U23+1) -> 10 | W23: =IF(OR(V23="",VALUE(V23)>EOMONTH(DATEVALUE($Z$1&$R$20&1),0)-EOMONTH(DATEVALUE($Z$1&$R$20&1),-1)-1),"",V23+1) -> 11 | X23: =IF(OR(W23="",VALUE(W23)>EOMONTH(DATEVALUE($Z$1&$R$20&1),0)-EOMONTH(DATEVALUE($Z$1&$R$20&1),-1)-1),"",W23+1) -> 12
B24: =IF(OR(H23="",VALUE(H23)>EOMONTH(DATEVALUE($Z$1&$B$20&1),0)-EOMONTH(DATEVALUE($Z$1&$B$20&1),-1)-1),"",H23+1) -> 12 | C24: =IF(OR(B24="",VALUE(B24)>EOMONTH(DATEVALUE($Z$1&$B$20&1),0)-EOMONTH(DATEVALUE($Z$1&$B$20&1),-1)-1),"",B24+1) -> 13 | D24: =IF(OR(C24="",VALUE(C24)>EOMONTH(DATEVALUE($Z$1&$B$20&1),0)-EOMONTH(DATEVALUE($Z$1&$B$20&1),-1)-1),"",C24+1) -> 14 | E24: =IF(OR(D24="",VALUE(D24)>EOMONTH(DATEVALUE($Z$1&$B$20&1),0)-EOMONTH(DATEVALUE($Z$1&$B$20&1),-1)-1),"",D24+1) -> 15 | F24: =IF(OR(E24="",VALUE(E24)>EOMONTH(DATEVALUE($Z$1&$B$20&1),0)-EOMONTH(DATEVALUE($Z$1&$B$20&1),-1)-1),"",E24+1) -> 16 | G24: =IF(OR(F24="",VALUE(F24)>EOMONTH(DATEVALUE($Z$1&$B$20&1),0)-EOMONTH(DATEVALUE($Z$1&$B$20&1),-1)-1),"",F24+1) -> 17 | H24: =IF(OR(G24="",VALUE(G24)>EOMONTH(DATEVALUE($Z$1&$B$20&1),0)-EOMONTH(DATEVALUE($Z$1&$B$20&1),-1)-1),"",G24+1) -> 18 | J24: =IF(OR(P23="",VALUE(P23)>EOMONTH(DATEVALUE($Z$1&$J$20&1),0)-EOMONTH(DATEVALUE($Z$1&$J$20&1),-1)-1),"",P23+1) -> 9 | K24: =IF(OR(J24="",VALUE(J24)>EOMONTH(DATEVALUE($Z$1&$J$20&1),0)-EOMONTH(DATEVALUE($Z$1&$J$20&1),-1)-1),"",J24+1) -> 10 | L24: =IF(OR(K24="",VALUE(K24)>EOMONTH(DATEVALUE($Z$1&$J$20&1),0)-EOMONTH(DATEVALUE($Z$1&$J$20&1),-1)-1),"",K24+1) -> 11 | M24: =IF(OR(L24="",VALUE(L24)>EOMONTH(DATEVALUE($Z$1&$J$20&1),0)-EOMONTH(DATEVALUE($Z$1&$J$20&1),-1)-1),"",L24+1) -> 12 | N24: =IF(OR(M24="",VALUE(M24)>EOMONTH(DATEVALUE($Z$1&$J$20&1),0)-EOMONTH(DATEVALUE($Z$1&$J$20&1),-1)-1),"",M24+1) -> 13 | O24: =IF(OR(N24="",VALUE(N24)>EOMONTH(DATEVALUE($Z$1&$J$20&1),0)-EOMONTH(DATEVALUE($Z$1&$J$20&1),-1)-1),"",N24+1) -> 14 | P24: =IF(OR(O24="",VALUE(O24)>EOMONTH(DATEVALUE($Z$1&$J$20&1),0)-EOMONTH(DATEVALUE($Z$1&$J$20&1),-1)-1),"",O24+1) -> 15 | R24: =IF(OR(X23="",VALUE(X23)>EOMONTH(DATEVALUE($Z$1&$R$20&1),0)-EOMONTH(DATEVALUE($Z$1&$R$20&1),-1)-1),"",X23+1) -> 13 | S24: =IF(OR(R24="",VALUE(R24)>EOMONTH(DATEVALUE($Z$1&$R$20&1),0)-EOMONTH(DATEVALUE($Z$1&$R$20&1),-1)-1),"",R24+1) -> 14 | T24: =IF(OR(S24="",VALUE(S24)>EOMONTH(DATEVALUE($Z$1&$R$20&1),0)-EOMONTH(DATEVALUE($Z$1&$R$20&1),-1)-1),"",S24+1) -> 15 | U24: =IF(OR(T24="",VALUE(T24)>EOMONTH(DATEVALUE($Z$1&$R$20&1),0)-EOMONTH(DATEVALUE($Z$1&$R$20&1),-1)-1),"",T24+1) -> 16 | V24: =IF(OR(U24="",VALUE(U24)>EOMONTH(DATEVALUE($Z$1&$R$20&1),0)-EOMONTH(DATEVALUE($Z$1&$R$20&1),-1)-1),"",U24+1) -> 17 | W24: =IF(OR(V24="",VALUE(V24)>EOMONTH(DATEVALUE($Z$1&$R$20&1),0)-EOMONTH(DATEVALUE($Z$1&$R$20&1),-1)-1),"",V24+1) -> 18 | X24: =IF(OR(W24="",VALUE(W24)>EOMONTH(DATEVALUE($Z$1&$R$20&1),0)-EOMONTH(DATEVALUE($Z$1&$R$20&1),-1)-1),"",W24+1) -> 19
B25: =IF(OR(H24="",VALUE(H24)>EOMONTH(DATEVALUE($Z$1&$B$20&1),0)-EOMONTH(DATEVALUE($Z$1&$B$20&1),-1)-1),"",H24+1) -> 19 | C25: =IF(OR(B25="",VALUE(B25)>EOMONTH(DATEVALUE($Z$1&$B$20&1),0)-EOMONTH(DATEVALUE($Z$1&$B$20&1),-1)-1),"",B25+1) -> 20 | D25: =IF(OR(C25="",VALUE(C25)>EOMONTH(DATEVALUE($Z$1&$B$20&1),0)-EOMONTH(DATEVALUE($Z$1&$B$20&1),-1)-1),"",C25+1) -> 21 | E25: =IF(OR(D25="",VALUE(D25)>EOMONTH(DATEVALUE($Z$1&$B$20&1),0)-EOMONTH(DATEVALUE($Z$1&$B$20&1),-1)-1),"",D25+1) -> 22 | F25: =IF(OR(E25="",VALUE(E25)>EOMONTH(DATEVALUE($Z$1&$B$20&1),0)-EOMONTH(DATEVALUE($Z$1&$B$20&1),-1)-1),"",E25+1) -> 23 | G25: =IF(OR(F25="",VALUE(F25)>EOMONTH(DATEVALUE($Z$1&$B$20&1),0)-EOMONTH(DATEVALUE($Z$1&$B$20&1),-1)-1),"",F25+1) -> 24 | H25: =IF(OR(G25="",VALUE(G25)>EOMONTH(DATEVALUE($Z$1&$B$20&1),0)-EOMONTH(DATEVALUE($Z$1&$B$20&1),-1)-1),"",G25+1) -> 25 | J25: =IF(OR(P24="",VALUE(P24)>EOMONTH(DATEVALUE($Z$1&$J$20&1),0)-EOMONTH(DATEVALUE($Z$1&$J$20&1),-1)-1),"",P24+1) -> 16 | K25: =IF(OR(J25="",VALUE(J25)>EOMONTH(DATEVALUE($Z$1&$J$20&1),0)-EOMONTH(DATEVALUE($Z$1&$J$20&1),-1)-1),"",J25+1) -> 17 | L25: =IF(OR(K25="",VALUE(K25)>EOMONTH(DATEVALUE($Z$1&$J$20&1),0)-EOMONTH(DATEVALUE($Z$1&$J$20&1),-1)-1),"",K25+1) -> 18 | M25: =IF(OR(L25="",VALUE(L25)>EOMONTH(DATEVALUE($Z$1&$J$20&1),0)-EOMONTH(DATEVALUE($Z$1&$J$20&1),-1)-1),"",L25+1) -> 19 | N25: =IF(OR(M25="",VALUE(M25)>EOMONTH(DATEVALUE($Z$1&$J$20&1),0)-EOMONTH(DATEVALUE($Z$1&$J$20&1),-1)-1),"",M25+1) -> 20 | O25: =IF(OR(N25="",VALUE(N25)>EOMONTH(DATEVALUE($Z$1&$J$20&1),0)-EOMONTH(DATEVALUE($Z$1&$J$20&1),-1)-1),"",N25+1) -> 21 | P25: =IF(OR(O25="",VALUE(O25)>EOMONTH(DATEVALUE($Z$1&$J$20&1),0)-EOMONTH(DATEVALUE($Z$1&$J$20&1),-1)-1),"",O25+1) -> 22 | R25: =IF(OR(X24="",VALUE(X24)>EOMONTH(DATEVALUE($Z$1&$R$20&1),0)-EOMONTH(DATEVALUE($Z$1&$R$20&1),-1)-1),"",X24+1) -> 20 | S25: =IF(OR(R25="",VALUE(R25)>EOMONTH(DATEVALUE($Z$1&$R$20&1),0)-EOMONTH(DATEVALUE($Z$1&$R$20&1),-1)-1),"",R25+1) -> 21 | T25: =IF(OR(S25="",VALUE(S25)>EOMONTH(DATEVALUE($Z$1&$R$20&1),0)-EOMONTH(DATEVALUE($Z$1&$R$20&1),-1)-1),"",S25+1) -> 22 | U25: =IF(OR(T25="",VALUE(T25)>EOMONTH(DATEVALUE($Z$1&$R$20&1),0)-EOMONTH(DATEVALUE($Z$1&$R$20&1),-1)-1),"",T25+1) -> 23 | V25: =IF(OR(U25="",VALUE(U25)>EOMONTH(DATEVALUE($Z$1&$R$20&1),0)-EOMONTH(DATEVALUE($Z$1&$R$20&1),-1)-1),"",U25+1) -> 24 | W25: =IF(OR(V25="",VALUE(V25)>EOMONTH(DATEVALUE($Z$1&$R$20&1),0)-EOMONTH(DATEVALUE($Z$1&$R$20&1),-1)-1),"",V25+1) -> 25 | X25: =IF(OR(W25="",VALUE(W25)>EOMONTH(DATEVALUE($Z$1&$R$20&1),0)-EOMONTH(DATEVALUE($Z$1&$R$20&1),-1)-1),"",W25+1) -> 26
B26: =IF(OR(H25="",VALUE(H25)>EOMONTH(DATEVALUE($Z$1&$B$20&1),0)-EOMONTH(DATEVALUE($Z$1&$B$20&1),-1)-1),"",H25+1) -> 26 | C26: =IF(OR(B26="",VALUE(B26)>EOMONTH(DATEVALUE($Z$1&$B$20&1),0)-EOMONTH(DATEVALUE($Z$1&$B$20&1),-1)-1),"",B26+1) -> 27 | D26: =IF(OR(C26="",VALUE(C26)>EOMONTH(DATEVALUE($Z$1&$B$20&1),0)-EOMONTH(DATEVALUE($Z$1&$B$20&1),-1)-1),"",C26+1) -> 28 | E26: =IF(OR(D26="",VALUE(D26)>EOMONTH(DATEVALUE($Z$1&$B$20&1),0)-EOMONTH(DATEVALUE($Z$1&$B$20&1),-1)-1),"",D26+1) -> 29 | F26: =IF(OR(E26="",VALUE(E26)>EOMONTH(DATEVALUE($Z$1&$B$20&1),0)-EOMONTH(DATEVALUE($Z$1&$B$20&1),-1)-1),"",E26+1) -> 30 | G26: =IF(OR(F26="",VALUE(F26)>EOMONTH(DATEVALUE($Z$1&$B$20&1),0)-EOMONTH(DATEVALUE($Z$1&$B$20&1),-1)-1),"",F26+1) -> 31 | H26: =IF(OR(G26="",VALUE(G26)>EOMONTH(DATEVALUE($Z$1&$B$20&1),0)-EOMONTH(DATEVALUE($Z$1&$B$20&1),-1)-1),"",G26+1) | J26: =IF(OR(P25="",VALUE(P25)>EOMONTH(DATEVALUE($Z$1&$J$20&1),0)-EOMONTH(DATEVALUE($Z$1&$J$20&1),-1)-1),"",P25+1) -> 23 | K26: =IF(OR(J26="",VALUE(J26)>EOMONTH(DATEVALUE($Z$1&$J$20&1),0)-EOMONTH(DATEVALUE($Z$1&$J$20&1),-1)-1),"",J26+1) -> 24 | L26: =IF(OR(K26="",VALUE(K26)>EOMONTH(DATEVALUE($Z$1&$J$20&1),0)-EOMONTH(DATEVALUE($Z$1&$J$20&1),-1)-1),"",K26+1) -> 25 | M26: =IF(OR(L26="",VALUE(L26)>EOMONTH(DATEVALUE($Z$1&$J$20&1),0)-EOMONTH(DATEVALUE($Z$1&$J$20&1),-1)-1),"",L26+1) -> 26 | N26: =IF(OR(M26="",VALUE(M26)>EOMONTH(DATEVALUE($Z$1&$J$20&1),0)-EOMONTH(DATEVALUE($Z$1&$J$20&1),-1)-1),"",M26+1) -> 27 | O26: =IF(OR(N26="",VALUE(N26)>EOMONTH(DATEVALUE($Z$1&$J$20&1),0)-EOMONTH(DATEVALUE($Z$1&$J$20&1),-1)-1),"",N26+1) -> 28 | P26: =IF(OR(O26="",VALUE(O26)>EOMONTH(DATEVALUE($Z$1&$J$20&1),0)-EOMONTH(DATEVALUE($Z$1&$J$20&1),-1)-1),"",O26+1) -> 29 | R26: =IF(OR(X25="",VALUE(X25)>EOMONTH(DATEVALUE($Z$1&$R$20&1),0)-EOMONTH(DATEVALUE($Z$1&$R$20&1),-1)-1),"",X25+1) -> 27 | S26: =IF(OR(R26="",VALUE(R26)>EOMONTH(DATEVALUE($Z$1&$R$20&1),0)-EOMONTH(DATEVALUE($Z$1&$R$20&1),-1)-1),"",R26+1) -> 28 | T26: =IF(OR(S26="",VALUE(S26)>EOMONTH(DATEVALUE($Z$1&$R$20&1),0)-EOMONTH(DATEVALUE($Z$1&$R$20&1),-1)-1),"",S26+1) -> 29 | U26: =IF(OR(T26="",VALUE(T26)>EOMONTH(DATEVALUE($Z$1&$R$20&1),0)-EOMONTH(DATEVALUE($Z$1&$R$20&1),-1)-1),"",T26+1) -> 30 | V26: =IF(OR(U26="",VALUE(U26)>EOMONTH(DATEVALUE($Z$1&$R$20&1),0)-EOMONTH(DATEVALUE($Z$1&$R$20&1),-1)-1),"",U26+1) | W26: =IF(OR(V26="",VALUE(V26)>EOMONTH(DATEVALUE($Z$1&$R$20&1),0)-EOMONTH(DATEVALUE($Z$1&$R$20&1),-1)-1),"",V26+1) | X26: =IF(OR(W26="",VALUE(W26)>EOMONTH(DATEVALUE($Z$1&$R$20&1),0)-EOMONTH(DATEVALUE($Z$1&$R$20&1),-1)-1),"",W26+1)
B27: =IF(OR(H26="",VALUE(H26)>EOMONTH(DATEVALUE($Z$1&$B$20&1),0)-EOMONTH(DATEVALUE($Z$1&$B$20&1),-1)-1),"",H26+1) | C27: =IF(OR(B27="",VALUE(B27)>EOMONTH(DATEVALUE($Z$1&$B$20&1),0)-EOMONTH(DATEVALUE($Z$1&$B$20&1),-1)-1),"",B27+1) | D27: =IF(OR(C27="",VALUE(C27)>EOMONTH(DATEVALUE($Z$1&$B$20&1),0)-EOMONTH(DATEVALUE($Z$1&$B$20&1),-1)-1),"",C27+1) | E27: =IF(OR(D27="",VALUE(D27)>EOMONTH(DATEVALUE($Z$1&$B$20&1),0)-EOMONTH(DATEVALUE($Z$1&$B$20&1),-1)-1),"",D27+1) | F27: =IF(OR(E27="",VALUE(E27)>EOMONTH(DATEVALUE($Z$1&$B$20&1),0)-EOMONTH(DATEVALUE($Z$1&$B$20&1),-1)-1),"",E27+1) | G27: =IF(OR(F27="",VALUE(F27)>EOMONTH(DATEVALUE($Z$1&$B$20&1),0)-EOMONTH(DATEVALUE($Z$1&$B$20&1),-1)-1),"",F27+1) | H27: =IF(OR(G27="",VALUE(G27)>EOMONTH(DATEVALUE($Z$1&$B$20&1),0)-EOMONTH(DATEVALUE($Z$1&$B$20&1),-1)-1),"",G27+1) | J27: =IF(OR(P26="",VALUE(P26)>EOMONTH(DATEVALUE($Z$1&$J$20&1),0)-EOMONTH(DATEVALUE($Z$1&$J$20&1),-1)-1),"",P26+1) -> 30 | K27: =IF(OR(J27="",VALUE(J27)>EOMONTH(DATEVALUE($Z$1&$J$20&1),0)-EOMONTH(DATEVALUE($Z$1&$J$20&1),-1)-1),"",J27+1) -> 31 | L27: =IF(OR(K27="",VALUE(K27)>EOMONTH(DATEVALUE($Z$1&$J$20&1),0)-EOMONTH(DATEVALUE($Z$1&$J$20&1),-1)-1),"",K27+1) | M27: =IF(OR(L27="",VALUE(L27)>EOMONTH(DATEVALUE($Z$1&$J$20&1),0)-EOMONTH(DATEVALUE($Z$1&$J$20&1),-1)-1),"",L27+1) | N27: =IF(OR(M27="",VALUE(M27)>EOMONTH(DATEVALUE($Z$1&$J$20&1),0)-EOMONTH(DATEVALUE($Z$1&$J$20&1),-1)-1),"",M27+1) | O27: =IF(OR(N27="",VALUE(N27)>EOMONTH(DATEVALUE($Z$1&$J$20&1),0)-EOMONTH(DATEVALUE($Z$1&$J$20&1),-1)-1),"",N27+1) | P27: =IF(OR(O27="",VALUE(O27)>EOMONTH(DATEVALUE($Z$1&$J$20&1),0)-EOMONTH(DATEVALUE($Z$1&$J$20&1),-1)-1),"",O27+1) | R27: =IF(OR(X26="",VALUE(X26)>EOMONTH(DATEVALUE($Z$1&$R$20&1),0)-EOMONTH(DATEVALUE($Z$1&$R$20&1),-1)-1),"",X26+1) | S27: =IF(OR(R27="",VALUE(R27)>EOMONTH(DATEVALUE($Z$1&$R$20&1),0)-EOMONTH(DATEVALUE($Z$1&$R$20&1),-1)-1),"",R27+1) | T27: =IF(OR(S27="",VALUE(S27)>EOMONTH(DATEVALUE($Z$1&$R$20&1),0)-EOMONTH(DATEVALUE($Z$1&$R$20&1),-1)-1),"",S27+1) | U27: =IF(OR(T27="",VALUE(T27)>EOMONTH(DATEVALUE($Z$1&$R$20&1),0)-EOMONTH(DATEVALUE($Z$1&$R$20&1),-1)-1),"",T27+1) | V27: =IF(OR(U27="",VALUE(U27)>EOMONTH(DATEVALUE($Z$1&$R$20&1),0)-EOMONTH(DATEVALUE($Z$1&$R$20&1),-1)-1),"",U27+1) | W27: =IF(OR(V27="",VALUE(V27)>EOMONTH(DATEVALUE($Z$1&$R$20&1),0)-EOMONTH(DATEVALUE($Z$1&$R$20&1),-1)-1),"",V27+1) | X27: =IF(OR(W27="",VALUE(W27)>EOMONTH(DATEVALUE($Z$1&$R$20&1),0)-EOMONTH(DATEVALUE($Z$1&$R$20&1),-1)-1),"",W27+1)
B29: OCTOBER | J29: NOVEMBER | R29: DECEMBER
B30: S | C30: M | D30: T | E30: W | F30: T | G30: F | H30: S | J30: S | K30: M | L30: T | M30: W | N30: T | O30: F | P30: S | R30: S | S30: M | T30: T | U30: W | V30: T | W30: F | X30: S
B31: =IF(WEEKDAY(DATEVALUE($Z$1&$B$29&1))=1,1,"") | C31: =IF(B31<>"",B31+1,IF(WEEKDAY(DATEVALUE($Z$1&$B$29&1))=2,1,"")) | D31: =IF(C31<>"",C31+1,IF(WEEKDAY(DATEVALUE($Z$1&$B$29&1))=3,1,"")) | E31: =IF(D31<>"",D31+1,IF(WEEKDAY(DATEVALUE($Z$1&$B$29&1))=4,1,"")) | F31: =IF(E31<>"",E31+1,IF(WEEKDAY(DATEVALUE($Z$1&$B$29&1))=5,1,"")) -> 1 | G31: =IF(F31<>"",F31+1,IF(WEEKDAY(DATEVALUE($Z$1&$B$29&1))=6,1,"")) -> 2 | H31: =IF(G31<>"",G31+1,IF(WEEKDAY(DATEVALUE($Z$1&$B$29&1))=7,1,"")) -> 3 | J31: =IF(WEEKDAY(DATEVALUE($Z$1&$J$29&1))=1,1,"") -> 1 | K31: =IF(J31<>"",J31+1,IF(WEEKDAY(DATEVALUE($Z$1&$J$29&1))=2,1,"")) -> 2 | L31: =IF(K31<>"",K31+1,IF(WEEKDAY(DATEVALUE($Z$1&$J$29&1))=3,1,"")) -> 3 | M31: =IF(L31<>"",L31+1,IF(WEEKDAY(DATEVALUE($Z$1&$J$29&1))=4,1,"")) -> 4 | N31: =IF(M31<>"",M31+1,IF(WEEKDAY(DATEVALUE($Z$1&$J$29&1))=5,1,"")) -> 5 | O31: =IF(N31<>"",N31+1,IF(WEEKDAY(DATEVALUE($Z$1&$J$29&1))=6,1,"")) -> 6 | P31: =IF(O31<>"",O31+1,IF(WEEKDAY(DATEVALUE($Z$1&$J$29&1))=7,1,"")) -> 7 | R31: =IF(WEEKDAY(DATEVALUE($Z$1&$R$29&1))=1,1,"") | S31: =IF(R31<>"",R31+1,IF(WEEKDAY(DATEVALUE($Z$1&$R$29&1))=2,1,"")) | T31: =IF(S31<>"",S31+1,IF(WEEKDAY(DATEVALUE($Z$1&$R$29&1))=3,1,"")) -> 1 | U31: =IF(T31<>"",T31+1,IF(WEEKDAY(DATEVALUE($Z$1&$R$29&1))=4,1,"")) -> 2 | V31: =IF(U31<>"",U31+1,IF(WEEKDAY(DATEVALUE($Z$1&$R$29&1))=5,1,"")) -> 3 | W31: =IF(V31<>"",V31+1,IF(WEEKDAY(DATEVALUE($Z$1&$R$29&1))=6,1,"")) -> 4 | X31: =IF(W31<>"",W31+1,IF(WEEKDAY(DATEVALUE($Z$1&$R$29&1))=7,1,"")) -> 5
B32: =IF(OR(H31="",VALUE(H31)>EOMONTH(DATEVALUE($Z$1&$B$29&1),0)-EOMONTH(DATEVALUE($Z$1&$B$29&1),-1)-1),"",H31+1) -> 4 | C32: =IF(OR(B32="",VALUE(B32)>EOMONTH(DATEVALUE($Z$1&$B$29&1),0)-EOMONTH(DATEVALUE($Z$1&$B$29&1),-1)-1),"",B32+1) -> 5 | D32: =IF(OR(C32="",VALUE(C32)>EOMONTH(DATEVALUE($Z$1&$B$29&1),0)-EOMONTH(DATEVALUE($Z$1&$B$29&1),-1)-1),"",C32+1) -> 6 | E32: =IF(OR(D32="",VALUE(D32)>EOMONTH(DATEVALUE($Z$1&$B$29&1),0)-EOMONTH(DATEVALUE($Z$1&$B$29&1),-1)-1),"",D32+1) -> 7 | F32: =IF(OR(E32="",VALUE(E32)>EOMONTH(DATEVALUE($Z$1&$B$29&1),0)-EOMONTH(DATEVALUE($Z$1&$B$29&1),-1)-1),"",E32+1) -> 8 | G32: =IF(OR(F32="",VALUE(F32)>EOMONTH(DATEVALUE($Z$1&$B$29&1),0)-EOMONTH(DATEVALUE($Z$1&$B$29&1),-1)-1),"",F32+1) -> 9 | H32: =IF(OR(G32="",VALUE(G32)>EOMONTH(DATEVALUE($Z$1&$B$29&1),0)-EOMONTH(DATEVALUE($Z$1&$B$29&1),-1)-1),"",G32+1) -> 10 | J32: =IF(OR(P31="",VALUE(P31)>EOMONTH(DATEVALUE($Z$1&$J$29&1),0)-EOMONTH(DATEVALUE($Z$1&$J$29&1),-1)-1),"",P31+1) -> 8 | K32: =IF(OR(J32="",VALUE(J32)>EOMONTH(DATEVALUE($Z$1&$J$29&1),0)-EOMONTH(DATEVALUE($Z$1&$J$29&1),-1)-1),"",J32+1) -> 9 | L32: =IF(OR(K32="",VALUE(K32)>EOMONTH(DATEVALUE($Z$1&$J$29&1),0)-EOMONTH(DATEVALUE($Z$1&$J$29&1),-1)-1),"",K32+1) -> 10 | M32: =IF(OR(L32="",VALUE(L32)>EOMONTH(DATEVALUE($Z$1&$J$29&1),0)-EOMONTH(DATEVALUE($Z$1&$J$29&1),-1)-1),"",L32+1) -> 11 | N32: =IF(OR(M32="",VALUE(M32)>EOMONTH(DATEVALUE($Z$1&$J$29&1),0)-EOMONTH(DATEVALUE($Z$1&$J$29&1),-1)-1),"",M32+1) -> 12 | O32: =IF(OR(N32="",VALUE(N32)>EOMONTH(DATEVALUE($Z$1&$J$29&1),0)-EOMONTH(DATEVALUE($Z$1&$J$29&1),-1)-1),"",N32+1) -> 13 | P32: =IF(OR(O32="",VALUE(O32)>EOMONTH(DATEVALUE($Z$1&$J$29&1),0)-EOMONTH(DATEVALUE($Z$1&$J$29&1),-1)-1),"",O32+1) -> 14 | R32: =IF(OR(X31="",VALUE(X31)>EOMONTH(DATEVALUE($Z$1&$R$29&1),0)-EOMONTH(DATEVALUE($Z$1&$R$29&1),-1)-1),"",X31+1) -> 6 | S32: =IF(OR(R32="",VALUE(R32)>EOMONTH(DATEVALUE($Z$1&$R$29&1),0)-EOMONTH(DATEVALUE($Z$1&$R$29&1),-1)-1),"",R32+1) -> 7 | T32: =IF(OR(S32="",VALUE(S32)>EOMONTH(DATEVALUE($Z$1&$R$29&1),0)-EOMONTH(DATEVALUE($Z$1&$R$29&1),-1)-1),"",S32+1) -> 8 | U32: =IF(OR(T32="",VALUE(T32)>EOMONTH(DATEVALUE($Z$1&$R$29&1),0)-EOMONTH(DATEVALUE($Z$1&$R$29&1),-1)-1),"",T32+1) -> 9 | V32: =IF(OR(U32="",VALUE(U32)>EOMONTH(DATEVALUE($Z$1&$R$29&1),0)-EOMONTH(DATEVALUE($Z$1&$R$29&1),-1)-1),"",U32+1) -> 10 | W32: =IF(OR(V32="",VALUE(V32)>EOMONTH(DATEVALUE($Z$1&$R$29&1),0)-EOMONTH(DATEVALUE($Z$1&$R$29&1),-1)-1),"",V32+1) -> 11 | X32: =IF(OR(W32="",VALUE(W32)>EOMONTH(DATEVALUE($Z$1&$R$29&1),0)-EOMONTH(DATEVALUE($Z$1&$R$29&1),-1)-1),"",W32+1) -> 12
B33: =IF(OR(H32="",VALUE(H32)>EOMONTH(DATEVALUE($Z$1&$B$29&1),0)-EOMONTH(DATEVALUE($Z$1&$B$29&1),-1)-1),"",H32+1) -> 11 | C33: =IF(OR(B33="",VALUE(B33)>EOMONTH(DATEVALUE($Z$1&$B$29&1),0)-EOMONTH(DATEVALUE($Z$1&$B$29&1),-1)-1),"",B33+1) -> 12 | D33: =IF(OR(C33="",VALUE(C33)>EOMONTH(DATEVALUE($Z$1&$B$29&1),0)-EOMONTH(DATEVALUE($Z$1&$B$29&1),-1)-1),"",C33+1) -> 13 | E33: =IF(OR(D33="",VALUE(D33)>EOMONTH(DATEVALUE($Z$1&$B$29&1),0)-EOMONTH(DATEVALUE($Z$1&$B$29&1),-1)-1),"",D33+1) -> 14 | F33: =IF(OR(E33="",VALUE(E33)>EOMONTH(DATEVALUE($Z$1&$B$29&1),0)-EOMONTH(DATEVALUE($Z$1&$B$29&1),-1)-1),"",E33+1) -> 15 | G33: =IF(OR(F33="",VALUE(F33)>EOMONTH(DATEVALUE($Z$1&$B$29&1),0)-EOMONTH(DATEVALUE($Z$1&$B$29&1),-1)-1),"",F33+1) -> 16 | H33: =IF(OR(G33="",VALUE(G33)>EOMONTH(DATEVALUE($Z$1&$B$29&1),0)-EOMONTH(DATEVALUE($Z$1&$B$29&1),-1)-1),"",G33+1) -> 17 | J33: =IF(OR(P32="",VALUE(P32)>EOMONTH(DATEVALUE($Z$1&$J$29&1),0)-EOMONTH(DATEVALUE($Z$1&$J$29&1),-1)-1),"",P32+1) -> 15 | K33: =IF(OR(J33="",VALUE(J33)>EOMONTH(DATEVALUE($Z$1&$J$29&1),0)-EOMONTH(DATEVALUE($Z$1&$J$29&1),-1)-1),"",J33+1) -> 16 | L33: =IF(OR(K33="",VALUE(K33)>EOMONTH(DATEVALUE($Z$1&$J$29&1),0)-EOMONTH(DATEVALUE($Z$1&$J$29&1),-1)-1),"",K33+1) -> 17 | M33: =IF(OR(L33="",VALUE(L33)>EOMONTH(DATEVALUE($Z$1&$J$29&1),0)-EOMONTH(DATEVALUE($Z$1&$J$29&1),-1)-1),"",L33+1) -> 18 | N33: =IF(OR(M33="",VALUE(M33)>EOMONTH(DATEVALUE($Z$1&$J$29&1),0)-EOMONTH(DATEVALUE($Z$1&$J$29&1),-1)-1),"",M33+1) -> 19 | O33: =IF(OR(N33="",VALUE(N33)>EOMONTH(DATEVALUE($Z$1&$J$29&1),0)-EOMONTH(DATEVALUE($Z$1&$J$29&1),-1)-1),"",N33+1) -> 20 | P33: =IF(OR(O33="",VALUE(O33)>EOMONTH(DATEVALUE($Z$1&$J$29&1),0)-EOMONTH(DATEVALUE($Z$1&$J$29&1),-1)-1),"",O33+1) -> 21 | R33: =IF(OR(X32="",VALUE(X32)>EOMONTH(DATEVALUE($Z$1&$R$29&1),0)-EOMONTH(DATEVALUE($Z$1&$R$29&1),-1)-1),"",X32+1) -> 13 | S33: =IF(OR(R33="",VALUE(R33)>EOMONTH(DATEVALUE($Z$1&$R$29&1),0)-EOMONTH(DATEVALUE($Z$1&$R$29&1),-1)-1),"",R33+1) -> 14 | T33: =IF(OR(S33="",VALUE(S33)>EOMONTH(DATEVALUE($Z$1&$R$29&1),0)-EOMONTH(DATEVALUE($Z$1&$R$29&1),-1)-1),"",S33+1) -> 15 | U33: =IF(OR(T33="",VALUE(T33)>EOMONTH(DATEVALUE($Z$1&$R$29&1),0)-EOMONTH(DATEVALUE($Z$1&$R$29&1),-1)-1),"",T33+1) -> 16 | V33: =IF(OR(U33="",VALUE(U33)>EOMONTH(DATEVALUE($Z$1&$R$29&1),0)-EOMONTH(DATEVALUE($Z$1&$R$29&1),-1)-1),"",U33+1) -> 17 | W33: =IF(OR(V33="",VALUE(V33)>EOMONTH(DATEVALUE($Z$1&$R$29&1),0)-EOMONTH(DATEVALUE($Z$1&$R$29&1),-1)-1),"",V33+1) -> 18 | X33: =IF(OR(W33="",VALUE(W33)>EOMONTH(DATEVALUE($Z$1&$R$29&1),0)-EOMONTH(DATEVALUE($Z$1&$R$29&1),-1)-1),"",W33+1) -> 19
B34: =IF(OR(H33="",VALUE(H33)>EOMONTH(DATEVALUE($Z$1&$B$29&1),0)-EOMONTH(DATEVALUE($Z$1&$B$29&1),-1)-1),"",H33+1) -> 18 | C34: =IF(OR(B34="",VALUE(B34)>EOMONTH(DATEVALUE($Z$1&$B$29&1),0)-EOMONTH(DATEVALUE($Z$1&$B$29&1),-1)-1),"",B34+1) -> 19 | D34: =IF(OR(C34="",VALUE(C34)>EOMONTH(DATEVALUE($Z$1&$B$29&1),0)-EOMONTH(DATEVALUE($Z$1&$B$29&1),-1)-1),"",C34+1) -> 20 | E34: =IF(OR(D34="",VALUE(D34)>EOMONTH(DATEVALUE($Z$1&$B$29&1),0)-EOMONTH(DATEVALUE($Z$1&$B$29&1),-1)-1),"",D34+1) -> 21 | F34: =IF(OR(E34="",VALUE(E34)>EOMONTH(DATEVALUE($Z$1&$B$29&1),0)-EOMONTH(DATEVALUE($Z$1&$B$29&1),-1)-1),"",E34+1) -> 22 | G34: =IF(OR(F34="",VALUE(F34)>EOMONTH(DATEVALUE($Z$1&$B$29&1),0)-EOMONTH(DATEVALUE($Z$1&$B$29&1),-1)-1),"",F34+1) -> 23 | H34: =IF(OR(G34="",VALUE(G34)>EOMONTH(DATEVALUE($Z$1&$B$29&1),0)-EOMONTH(DATEVALUE($Z$1&$B$29&1),-1)-1),"",G34+1) -> 24 | J34: =IF(OR(P33="",VALUE(P33)>EOMONTH(DATEVALUE($Z$1&$J$29&1),0)-EOMONTH(DATEVALUE($Z$1&$J$29&1),-1)-1),"",P33+1) -> 22 | K34: =IF(OR(J34="",VALUE(J34)>EOMONTH(DATEVALUE($Z$1&$J$29&1),0)-EOMONTH(DATEVALUE($Z$1&$J$29&1),-1)-1),"",J34+1) -> 23 | L34: =IF(OR(K34="",VALUE(K34)>EOMONTH(DATEVALUE($Z$1&$J$29&1),0)-EOMONTH(DATEVALUE($Z$1&$J$29&1),-1)-1),"",K34+1) -> 24 | M34: =IF(OR(L34="",VALUE(L34)>EOMONTH(DATEVALUE($Z$1&$J$29&1),0)-EOMONTH(DATEVALUE($Z$1&$J$29&1),-1)-1),"",L34+1) -> 25 | N34: =IF(OR(M34="",VALUE(M34)>EOMONTH(DATEVALUE($Z$1&$J$29&1),0)-EOMONTH(DATEVALUE($Z$1&$J$29&1),-1)-1),"",M34+1) -> 26 | O34: =IF(OR(N34="",VALUE(N34)>EOMONTH(DATEVALUE($Z$1&$J$29&1),0)-EOMONTH(DATEVALUE($Z$1&$J$29&1),-1)-1),"",N34+1) -> 27 | P34: =IF(OR(O34="",VALUE(O34)>EOMONTH(DATEVALUE($Z$1&$J$29&1),0)-EOMONTH(DATEVALUE($Z$1&$J$29&1),-1)-1),"",O34+1) -> 28 | R34: =IF(OR(X33="",VALUE(X33)>EOMONTH(DATEVALUE($Z$1&$R$29&1),0)-EOMONTH(DATEVALUE($Z$1&$R$29&1),-1)-1),"",X33+1) -> 20 | S34: =IF(OR(R34="",VALUE(R34)>EOMONTH(DATEVALUE($Z$1&$R$29&1),0)-EOMONTH(DATEVALUE($Z$1&$R$29&1),-1)-1),"",R34+1) -> 21 | T34: =IF(OR(S34="",VALUE(S34)>EOMONTH(DATEVALUE($Z$1&$R$29&1),0)-EOMONTH(DATEVALUE($Z$1&$R$29&1),-1)-1),"",S34+1) -> 22 | U34: =IF(OR(T34="",VALUE(T34)>EOMONTH(DATEVALUE($Z$1&$R$29&1),0)-EOMONTH(DATEVALUE($Z$1&$R$29&1),-1)-1),"",T34+1) -> 23 | V34: =IF(OR(U34="",VALUE(U34)>EOMONTH(DATEVALUE($Z$1&$R$29&1),0)-EOMONTH(DATEVALUE($Z$1&$R$29&1),-1)-1),"",U34+1) -> 24 | W34: =IF(OR(V34="",VALUE(V34)>EOMONTH(DATEVALUE($Z$1&$R$29&1),0)-EOMONTH(DATEVALUE($Z$1&$R$29&1),-1)-1),"",V34+1) -> 25 | X34: =IF(OR(W34="",VALUE(W34)>EOMONTH(DATEVALUE($Z$1&$R$29&1),0)-EOMONTH(DATEVALUE($Z$1&$R$29&1),-1)-1),"",W34+1) -> 26
B35: =IF(OR(H34="",VALUE(H34)>EOMONTH(DATEVALUE($Z$1&$B$29&1),0)-EOMONTH(DATEVALUE($Z$1&$B$29&1),-1)-1),"",H34+1) -> 25 | C35: =IF(OR(B35="",VALUE(B35)>EOMONTH(DATEVALUE($Z$1&$B$29&1),0)-EOMONTH(DATEVALUE($Z$1&$B$29&1),-1)-1),"",B35+1) -> 26 | D35: =IF(OR(C35="",VALUE(C35)>EOMONTH(DATEVALUE($Z$1&$B$29&1),0)-EOMONTH(DATEVALUE($Z$1&$B$29&1),-1)-1),"",C35+1) -> 27 | E35: =IF(OR(D35="",VALUE(D35)>EOMONTH(DATEVALUE($Z$1&$B$29&1),0)-EOMONTH(DATEVALUE($Z$1&$B$29&1),-1)-1),"",D35+1) -> 28 | F35: =IF(OR(E35="",VALUE(E35)>EOMONTH(DATEVALUE($Z$1&$B$29&1),0)-EOMONTH(DATEVALUE($Z$1&$B$29&1),-1)-1),"",E35+1) -> 29 | G35: =IF(OR(F35="",VALUE(F35)>EOMONTH(DATEVALUE($Z$1&$B$29&1),0)-EOMONTH(DATEVALUE($Z$1&$B$29&1),-1)-1),"",F35+1) -> 30 | H35: =IF(OR(G35="",VALUE(G35)>EOMONTH(DATEVALUE($Z$1&$B$29&1),0)-EOMONTH(DATEVALUE($Z$1&$B$29&1),-1)-1),"",G35+1) -> 31 | J35: =IF(OR(P34="",VALUE(P34)>EOMONTH(DATEVALUE($Z$1&$J$29&1),0)-EOMONTH(DATEVALUE($Z$1&$J$29&1),-1)-1),"",P34+1) -> 29 | K35: =IF(OR(J35="",VALUE(J35)>EOMONTH(DATEVALUE($Z$1&$J$29&1),0)-EOMONTH(DATEVALUE($Z$1&$J$29&1),-1)-1),"",J35+1) -> 30 | L35: =IF(OR(K35="",VALUE(K35)>EOMONTH(DATEVALUE($Z$1&$J$29&1),0)-EOMONTH(DATEVALUE($Z$1&$J$29&1),-1)-1),"",K35+1) | M35: =IF(OR(L35="",VALUE(L35)>EOMONTH(DATEVALUE($Z$1&$J$29&1),0)-EOMONTH(DATEVALUE($Z$1&$J$29&1),-1)-1),"",L35+1) | N35: =IF(OR(M35="",VALUE(M35)>EOMONTH(DATEVALUE($Z$1&$J$29&1),0)-EOMONTH(DATEVALUE($Z$1&$J$29&1),-1)-1),"",M35+1) | O35: =IF(OR(N35="",VALUE(N35)>EOMONTH(DATEVALUE($Z$1&$J$29&1),0)-EOMONTH(DATEVALUE($Z$1&$J$29&1),-1)-1),"",N35+1) | P35: =IF(OR(O35="",VALUE(O35)>EOMONTH(DATEVALUE($Z$1&$J$29&1),0)-EOMONTH(DATEVALUE($Z$1&$J$29&1),-1)-1),"",O35+1) | R35: =IF(OR(X34="",VALUE(X34)>EOMONTH(DATEVALUE($Z$1&$R$29&1),0)-EOMONTH(DATEVALUE($Z$1&$R$29&1),-1)-1),"",X34+1) -> 27 | S35: =IF(OR(R35="",VALUE(R35)>EOMONTH(DATEVALUE($Z$1&$R$29&1),0)-EOMONTH(DATEVALUE($Z$1&$R$29&1),-1)-1),"",R35+1) -> 28 | T35: =IF(OR(S35="",VALUE(S35)>EOMONTH(DATEVALUE($Z$1&$R$29&1),0)-EOMONTH(DATEVALUE($Z$1&$R$29&1),-1)-1),"",S35+1) -> 29 | U35: =IF(OR(T35="",VALUE(T35)>EOMONTH(DATEVALUE($Z$1&$R$29&1),0)-EOMONTH(DATEVALUE($Z$1&$R$29&1),-1)-1),"",T35+1) -> 30 | V35: =IF(OR(U35="",VALUE(U35)>EOMONTH(DATEVALUE($Z$1&$R$29&1),0)-EOMONTH(DATEVALUE($Z$1&$R$29&1),-1)-1),"",U35+1) -> 31 | W35: =IF(OR(V35="",VALUE(V35)>EOMONTH(DATEVALUE($Z$1&$R$29&1),0)-EOMONTH(DATEVALUE($Z$1&$R$29&1),-1)-1),"",V35+1) | X35: =IF(OR(W35="",VALUE(W35)>EOMONTH(DATEVALUE($Z$1&$R$29&1),0)-EOMONTH(DATEVALUE($Z$1&$R$29&1),-1)-1),"",W35+1)
B36: =IF(OR(H35="",VALUE(H35)>EOMONTH(DATEVALUE($Z$1&$B$29&1),0)-EOMONTH(DATEVALUE($Z$1&$B$29&1),-1)-1),"",H35+1) | C36: =IF(OR(B36="",VALUE(B36)>EOMONTH(DATEVALUE($Z$1&$B$29&1),0)-EOMONTH(DATEVALUE($Z$1&$B$29&1),-1)-1),"",B36+1) | D36: =IF(OR(C36="",VALUE(C36)>EOMONTH(DATEVALUE($Z$1&$B$29&1),0)-EOMONTH(DATEVALUE($Z$1&$B$29&1),-1)-1),"",C36+1) | E36: =IF(OR(D36="",VALUE(D36)>EOMONTH(DATEVALUE($Z$1&$B$29&1),0)-EOMONTH(DATEVALUE($Z$1&$B$29&1),-1)-1),"",D36+1) | F36: =IF(OR(E36="",VALUE(E36)>EOMONTH(DATEVALUE($Z$1&$B$29&1),0)-EOMONTH(DATEVALUE($Z$1&$B$29&1),-1)-1),"",E36+1) | G36: =IF(OR(F36="",VALUE(F36)>EOMONTH(DATEVALUE($Z$1&$B$29&1),0)-EOMONTH(DATEVALUE($Z$1&$B$29&1),-1)-1),"",F36+1) | H36: =IF(OR(G36="",VALUE(G36)>EOMONTH(DATEVALUE($Z$1&$B$29&1),0)-EOMONTH(DATEVALUE($Z$1&$B$29&1),-1)-1),"",G36+1) | J36: =IF(OR(P35="",VALUE(P35)>EOMONTH(DATEVALUE($Z$1&$J$29&1),0)-EOMONTH(DATEVALUE($Z$1&$J$29&1),-1)-1),"",P35+1) | K36: =IF(OR(J36="",VALUE(J36)>EOMONTH(DATEVALUE($Z$1&$J$29&1),0)-EOMONTH(DATEVALUE($Z$1&$J$29&1),-1)-1),"",J36+1) | L36: =IF(OR(K36="",VALUE(K36)>EOMONTH(DATEVALUE($Z$1&$J$29&1),0)-EOMONTH(DATEVALUE($Z$1&$J$29&1),-1)-1),"",K36+1) | M36: =IF(OR(L36="",VALUE(L36)>EOMONTH(DATEVALUE($Z$1&$J$29&1),0)-EOMONTH(DATEVALUE($Z$1&$J$29&1),-1)-1),"",L36+1) | N36: =IF(OR(M36="",VALUE(M36)>EOMONTH(DATEVALUE($Z$1&$J$29&1),0)-EOMONTH(DATEVALUE($Z$1&$J$29&1),-1)-1),"",M36+1) | O36: =IF(OR(N36="",VALUE(N36)>EOMONTH(DATEVALUE($Z$1&$J$29&1),0)-EOMONTH(DATEVALUE($Z$1&$J$29&1),-1)-1),"",N36+1) | P36: =IF(OR(O36="",VALUE(O36)>EOMONTH(DATEVALUE($Z$1&$J$29&1),0)-EOMONTH(DATEVALUE($Z$1&$J$29&1),-1)-1),"",O36+1) | R36: =IF(OR(X35="",VALUE(X35)>EOMONTH(DATEVALUE($Z$1&$R$29&1),0)-EOMONTH(DATEVALUE($Z$1&$R$29&1),-1)-1),"",X35+1) | S36: =IF(OR(R36="",VALUE(R36)>EOMONTH(DATEVALUE($Z$1&$R$29&1),0)-EOMONTH(DATEVALUE($Z$1&$R$29&1),-1)-1),"",R36+1) | T36: =IF(OR(S36="",VALUE(S36)>EOMONTH(DATEVALUE($Z$1&$R$29&1),0)-EOMONTH(DATEVALUE($Z$1&$R$29&1),-1)-1),"",S36+1) | U36: =IF(OR(T36="",VALUE(T36)>EOMONTH(DATEVALUE($Z$1&$R$29&1),0)-EOMONTH(DATEVALUE($Z$1&$R$29&1),-1)-1),"",T36+1) | V36: =IF(OR(U36="",VALUE(U36)>EOMONTH(DATEVALUE($Z$1&$R$29&1),0)-EOMONTH(DATEVALUE($Z$1&$R$29&1),-1)-1),"",U36+1) | W36: =IF(OR(V36="",VALUE(V36)>EOMONTH(DATEVALUE($Z$1&$R$29&1),0)-EOMONTH(DATEVALUE($Z$1&$R$29&1),-1)-1),"",V36+1) | X36: =IF(OR(W36="",VALUE(W36)>EOMONTH(DATEVALUE($Z$1&$R$29&1),0)-EOMONTH(DATEVALUE($Z$1&$R$29&1),-1)-1),"",W36+1)

Sheet Customize your calendar
B1: Go to Format >> Theme
B2: Bring your personal style into your annual planning
B3: This calendar will automatically update based on the year. You can also manually change the year in the first sheet. Explore 16 different themes to personalize your calendar - Simply go to the "Format" menu and select "Theme" - Browse and select from one of the preset Themes in the side panel - Use the themes as-is or you can add your own style by clicking "Customize"
B6: Streamline
B9: Retro
B12: Coral
B14: TIP: Insert images into cells by using: Insert >> Image >> Image in cell

Sheet Instructions
A1: # | B1: TTP TRACKER: INSTRUCTIONS | D1: Promo Name: | E1: ='Promo Info'!C1 -> #REF!
A2: ### | B2: WHAT IS THIS THING?
A3: - | B3: TTP Tracker is a tool for planning monthly resources for your desired STT boost goal. | D3: Length: | E3: ='Promo Info'!F2 -> #REF! | F3: =TEXT('Promo Info'!C2,"mm/dd") -> #REF! | G3: =TEXT('Promo Info'!C3,"mm/dd") -> #REF!
A4: ### | B4: GETTING STARTED:
A5: - | B5: Results are ESTIMATED! | D5: UC | E5: ='Promo Info'!L5 -> #REF!
A6: - | B6: On a web browser, Click File > Make a Copy. Or on the Google Sheets app ... > Share & Export > Make a Copy | E6: 250
A7: - | B7: Fill out any Light Green cells. Results are displayed in Blue cells.
A8: ### | B8: MORE COMING SOON...
A9: -
A12: -
A15: ###
A16: -
A17: -

Sheet Boostimator 26
B1: BOOSTIMATOR 26 | E1: FINAL OVR: | F1: =sum(K40:Q40,L45:P45,K52:R52,L57:Q57,M64:P64,R33) -> 3605.7495 | G1: TTP NEEDED: | H1: =sum(O61,P49,P37)-sum(O28,P16,P4) -> 130500 | I1: by phredd & jawabomb
B2: MY GOAL | E2: TARGET OVR: | F2: 3600
B3: MY CURRENT LINEUP | E3: CURRENT OVR: | F3: =SUM(B7:H7,C12:G12,B19:I19,C24:H24,D31:G31) -> 3470.3 | K3: QB | L3: HB/FB | M3: TE | N3: WR | O3: C/OG/OT | P3: COST
B4: OFFENSE | C4: RANK: | D4: 21 | K4: =vlookup($D$4,'Boost Data'!$A$1:$F$52,2,0) -> 9 | L4: =vlookup($D$4,'Boost Data'!$A$1:$F$52,3,0) -> 9 | M4: =vlookup($D$4,'Boost Data'!$A$1:$F$52,4,0) -> 9 | N4: =vlookup($D$4,'Boost Data'!$A$1:$F$52,5,0) -> 9 | O4: =vlookup($D$4,'Boost Data'!$A$1:$F$52,6,0) -> 9 | P4: =VLOOKUP(D4,'Boost Data'!$A$1:$G$52,7,0) -> 16660
K5: =hlookup(K6,$K3:$O4,2,0)/100 -> 0.09 | L5: =hlookup(L6,$K3:$O4,2,0)/100 -> 0.09 | M5: =hlookup(M6,$K3:$O4,2,0)/100 -> 0.09 | N5: =hlookup(N6,$K3:$O4,2,0)/100 -> 0.09 | O5: =hlookup(O6,$K3:$O4,2,0)/100 -> 0.09 | P5: =hlookup(P6,$K3:$O4,2,0)/100 -> 0.09 | Q5: =hlookup(Q6,$K3:$O4,2,0)/100 -> 0.09
B6: WR1 | C6: LEFT OT | D6: LEFT OG | E6: C | F6: RIGHT OG | G6: RIGHT OT | H6: WR2 | K6: WR | L6: C/OG/OT | M6: C/OG/OT | N6: C/OG/OT | O6: C/OG/OT | P6: C/OG/OT | Q6: WR
B7: 141 | C7: 99 | D7: 106 | E7: 106 | F7: 127 | G7: 140 | H7: 121 | K7: =(B7-K8-K9)/(1+K5) -> 124.77064 | L7: =(C7-L8-L9)/(1+L5) -> 90.825688 | M7: =(D7-M8-M9)/(1+M5) -> 97.247706 | N7: =(E7-N8-N9)/(1+N5) -> 97.247706 | O7: =(F7-O8-O9)/(1+O5) -> 116.51376 | P7: =(G7-P8-P9)/(1+P5) -> 123.85321 | Q7: =(H7-Q8-Q9)/(1+Q5) -> 111.00917
B8: Mythic +1 | G8: Mythic +1 | K8: =if(ISBLANK(B8)=FALSE,$P$28,0) -> 5 | L8: =if(ISBLANK(C8)=FALSE,$P$28,0) -> 0 | M8: =if(ISBLANK(D8)=FALSE,$P$28,0) -> 0 | N8: =if(ISBLANK(E8)=FALSE,$P$28,0) -> 0 | O8: =if(ISBLANK(F8)=FALSE,$P$28,0) -> 0 | P8: =if(ISBLANK(G8)=FALSE,$P$28,0) -> 5 | Q8: =if(ISBLANK(H8)=FALSE,$P$28,0) -> 0
